Workbook

Sheet כל הרשימות
A1: מפלגה | B1: מיקום | C1: שם | D1: גבר/אישה
A2: מפלגת העבודה בראשות מרב מיכאלי | B2: 1 | C2: מיכאלי מירב
A3: מפלגת העבודה בראשות מרב מיכאלי | B3: 2 | C3: לזימי נעמה
A4: מפלגת העבודה בראשות מרב מיכאלי | B4: 3 | C4: קריב גלעד
A5: מפלגת העבודה בראשות מרב מיכאלי | B5: 4 | C5: רייטן מרום אפרת
A6: מפלגת העבודה בראשות מרב מיכאלי | B6: 5 | C6: שפע רם
A7: מפלגת העבודה בראשות מרב מיכאלי | B7: 6 | C7: מואטי אמילי חיה
A8: מפלגת העבודה בראשות מרב מיכאלי | B8: 7 | C8: פינק יאיר
A9: מפלגת העבודה בראשות מרב מיכאלי | B9: 8 | C9: מראענה אבתיסאם
A10: מפלגת העבודה בראשות מרב מיכאלי | B10: 9 | C10: בר לב עמר ישראל
A11: מפלגת העבודה בראשות מרב מיכאלי | B11: 10 | C11: ברון רון מהרטיה
A12: מפלגת העבודה בראשות מרב מיכאלי | B12: 11 | C12: ח'ניפס אמיר
A13: מפלגת העבודה בראשות מרב מיכאלי | B13: 12 | C13: נורי שקד מאיה
... A1413: דעת טוב ורע וברית שבט אברהם-עלה ירוק ואוסרת אל איסלמיה | B1413: 16 | C1413: קדישא אדיר

Sheet מסונן
A1: מפלגה | B1: מיקום | C1: שם | D1: מגדר
A2: מפלגת העבודה בראשות מרב מיכאלי | B2: 1 | C2: מיכאלי מירב | D2: נ
A3: מפלגת העבודה בראשות מרב מיכאלי | B3: 2 | C3: לזימי נעמה | D3: נ
A4: מפלגת העבודה בראשות מרב מיכאלי | B4: 3 | C4: קריב גלעד | D4: ז
A5: מפלגת העבודה בראשות מרב מיכאלי | B5: 4 | C5: רייטן מרום אפרת | D5: נ
A6: מפלגת העבודה בראשות מרב מיכאלי | B6: 5 | C6: שפע רם | D6: ז
A7: מפלגת העבודה בראשות מרב מיכאלי | B7: 6 | C7: מואטי אמילי חיה | D7: נ
A8: מפלגת העבודה בראשות מרב מיכאלי | B8: 7 | C8: פינק יאיר | D8: ז
A9: מפלגת העבודה בראשות מרב מיכאלי | B9: 8 | C9: מראענה אבתיסאם | D9: נ
A10: מפלגת העבודה בראשות מרב מיכאלי | B10: 9 | C10: בר לב עמר ישראל | D10: ז
A11: מפלגת העבודה בראשות מרב מיכאלי | B11: 10 | C11: ברוך רון מהרטיה | D11: נ
A12: מפלגת העבודה בראשות מרב מיכאלי | B12: 11 | C12: ח'ניפס אמיר | D12: ז
A13: מפלגת העבודה בראשות מרב מיכאלי | B13: 12 | C13: נורי שקד מאיה | D13: ז
... A1151: התאחדות הספרדים שומרי תורה תנועתו של מרן הרב עובדיה יוסף זצ"ל | B1151: 120 | C1151: בעדני חיים אהרון | D1151: ז

Sheet Sheet1
A1: מפלגה
A2: מפלגת העבודה בראשות מרב מיכאלי
A3: הבית היהודי בראשות איילת שקד
A4: יהדות התורה והשבת אגודת ישראל – דגל התורה
A5: בל"ד - אלתג'מוע אלווטני אלדמוקרטי בראשות סמי אבו שחאדה
A6: חד"ש תע"ל בראשות איימן עודה ואחמד טיבי
A7: הציונות הדתית בראשות בצלאל סמוטריץ ועוצמה יהודית בראשות איתמר בן גביר
A8: המחנה הממלכתי בהנהגת בני גנץ לראשות הממשלה
A9: ישראל ביתנו בראשות אביגדור ליברמן
A10: הליכוד בהנהגת בנימין נתניהו לראשות הממשלה
A11: מרצ השמאל של ישראל בראשות זהבה גלאון
A12: הרשימה הערבית המאוחדת
... A14: התאחדות הספרדים שומרי תורה תנועתו של מרן הרב עובדיה יוסף זצ"ל

Sheet חישוב
A1: מפלגה | B1: מנדטים בסקר | C1: כמות נשים צפויה | D1: כמות גברים צפויה
A2: הליכוד | B2: 26 | C2: =COUNTIFS(מסונן!A:A,Sheet1!A10,מסונן!D:D,"נ",מסונן!B:B,"<=" & חישוב!B2) | D2: =B2-C2
A3: ישראל ביתינו | B3: 10 | C3: =COUNTIFS(מסונן!A:A,Sheet1!A9,מסונן!D:D,"נ",מסונן!B:B,"<=" & חישוב!B3) | D3: =B3-C3
A4: המחנה הממלכתי | B4: 7 | C4: =COUNTIFS(מסונן!A:A,Sheet1!A8,מסונן!D:D,"נ",מסונן!B:B,"<=" & חישוב!B4) | D4: =B4-C4
A5: הדמוקרטים | B5: 11 | C5: =COUNTIFS(מסונן!A:A,Sheet1!A2,מסונן!D:D,"נ",מסונן!B:B,"<=" & חישוב!B5/2)+COUNTIFS(מסונן!A:A,Sheet1!A11,מסונן!D:D,"נ",מסונן!B:B,"<=" & חישוב!B5/2) | D5: =B5-C5
A6: יש עתיד | B6: 9 | C6: =COUNTIFS(מסונן!A:A,Sheet1!A13,מסונן!D:D,"נ",מסונן!B:B,"<=" & חישוב!B6) | D6: =B6-C6
A7: ש"ס | B7: 10 | C7: =COUNTIFS(מסונן!A:A,Sheet1!A14,מסונן!D:D,"נ",מסונן!B:B,"<=" & חישוב!B7) | D7: =B7-C7
A8: יהדות התורה | B8: 7 | C8: =COUNTIFS(מסונן!A:A,Sheet1!A4,מסונן!D:D,"נ",מסונן!B:B,"<=" & חישוב!B8) | D8: =B8-C8
A9: עוצמה יהודית | B9: 6 | C9: =COUNTIFS(מסונן!A:A,Sheet1!A7,מסונן!D:D,"נ",מסונן!B:B,"<=" & חישוב!B9) | D9: =B9-C9
A10: רע"מ | B10: 6 | C10: =COUNTIFS(מסונן!A:A,Sheet1!A12,מסונן!D:D,"נ",מסונן!B:B,"<=" & חישוב!B10) | D10: =B10-C10
A11: חדש-תע"ל | B11: 4 | C11: =COUNTIFS(מסונן!A:A,Sheet1!A6,מסונן!D:D,"נ",מסונן!B:B,"<=" & חישוב!B11) | D11: =B11-C11
A12: הציונות הדתית | B12: 0 | C12: =COUNTIFS(מסונן!A:A,Sheet1!A7,מסונן!D:D,"נ",מסונן!B:B,"<=" & חישוב!B12) | D12: =B12-C12

Sheet סקר 2026
A1: מפלגה | B1: ממוצע המדד (סקר) | C1: מעוגל | D1: מנדטים צפויים (סופי)
A2: הליכוד | B2: 23.2 | C2: =ROUND(B2,0) | D2: =IF(C2<=3,0,C2)
A3: ישר! | B3: 22.5 | C3: =ROUND(B3,0) | D3: =IF(C3<=3,0,C3)
A4: ביחד (בנט-לפיד) | B4: 13.3 | C4: =ROUND(B4,0) | D4: =IF(C4<=3,0,C4)
A5: הדמוקרטים | B5: 10 | C5: =ROUND(B5,0) | D5: =IF(C5<=3,0,C5)
A6: ישראל ביתנו | B6: 9.2 | C6: =ROUND(B6,0) | D6: =IF(C6<=3,0,C6)
A7: ש"ס | B7: 8.1 | C7: =ROUND(B7,0) | D7: =IF(C7<=3,0,C7)
A8: עוצמה יהודית | B8: 7.8 | C8: =ROUND(B8,0) | D8: =IF(C8<=3,0,C8)
A9: יהדות התורה | B9: 8 | C9: =ROUND(B9,0) | D9: =IF(C9<=3,0,C9)
A10: חדש תע"ל | B10: 5.3 | C10: =ROUND(B10,0) | D10: =IF(C10<=3,0,C10)
A11: הציונות הדתית | B11: 4.8 | C11: =ROUND(B11,0) | D11: =IF(C11<=3,0,C11)
A12: רע"מ | B12: 5 | C12: =ROUND(B12,0) | D12: =IF(C12<=3,0,C12)
A13: טרופר-הנדל | B13: 3.4 | C13: =ROUND(B13,0) | D13: =IF(C13<=3,0,C13)
... A16: רשימה ערבית מאוחדת | B16: 0.6 | C16: =ROUND(B16,0) | D16: =IF(C16<=3,0,C16)

Sheet מועמדים 2026
A1: מפלגה | B1: מיקום | C1: שם | D1: מגדר | E1: ודאות/מקור
A2: ביחד (בנט-לפיד) | B2: 1 | C2: נפתלי בנט | D2: ז | E2: רשמי - מוביל הרשימה
A3: ביחד (בנט-לפיד) | B3: 2 | C3: יאיר לפיד | D3: ז | E3: יו"ר יש עתיד, ממוקם מס' 2 באומדן
A4: ביחד (בנט-לפיד) | B4: 3 | C4: אורנה ברביבאי | D4: נ | E4: חברת כנסת מכהנת ביש עתיד, מס' 2 ברשימת יש עתיד הרשמית (kan.org.il) - בתוך 14 המנדטים (תוקן: הייתה בטעות אלעזר שטרן, שדורג נמוך מדי)
A5: ביחד (בנט-לפיד) | B5: 4 | C5: מאיר כהן | D5: ז | E5: חבר/ת כנסת מכהן/ת ביש עתיד (ערוץ כנסת, knesset.tv) - בתוך 14 המנדטים לפי היחס המשוער בין בנט ללפיד
A6: ביחד (בנט-לפיד) | B6: 5 | C6: קארין אלהרר | D6: נ | E6: חבר/ת כנסת מכהן/ת ביש עתיד (ערוץ כנסת, knesset.tv) - בתוך 14 המנדטים לפי היחס המשוער בין בנט ללפיד
A7: ביחד (בנט-לפיד) | B7: 6 | C7: מירב כהן | D7: נ | E7: חבר/ת כנסת מכהן/ת ביש עתיד (ערוץ כנסת, knesset.tv) - בתוך 14 המנדטים לפי היחס המשוער בין בנט ללפיד
A8: ביחד (בנט-לפיד) | B8: 7 | C8: יואל רזבוזוב | D8: ז | E8: חבר כנסת מכהן ביש עתיד, מס' 6 ברשימת יש עתיד הרשמית (kan.org.il) - בתוך 14 המנדטים (תוקן: היה בטעות מיקי לוי, שדורג נמוך מדי)
A9: ביחד (בנט-לפיד) | B9: 8 | C9: נעם תיבון | D9: ז | E9: דווח בתקשורת (צד בנט), סדר משוער - בתוך 14 המנדטים
A10: ביחד (בנט-לפיד) | B10: 9 | C10: קרן טרנר | D10: נ | E10: דווח בתקשורת (צד בנט), סדר משוער - בתוך 14 המנדטים
A11: ביחד (בנט-לפיד) | B11: 10 | C11: לירן אבישר בן-חורין | D11: נ | E11: דווח בתקשורת (צד בנט), סדר משוער - בתוך 14 המנדטים
A12: ביחד (בנט-לפיד) | B12: 11 | C12: יונתן שלו | D12: ז | E12: דווח בתקשורת (צד בנט), סדר משוער - בתוך 14 המנדטים
A13: ביחד (בנט-לפיד) | B13: 12 | C13: ניר נובק | D13: ז | E13: דווח בתקשורת (צד בנט), סדר משוער - בתוך 14 המנדטים (הועלה למקום זה לאחר הסרת גילת בנט)
... A118: עוצמה יהודית | B118: 7 | C118: יצחק קרויזר | D118: ז | E118: חבר/ת כנסת מכהן/ת
A119: עוצמה יהודית | B119: 8 | C119: (לא אותר מועמד) | E119: לא אותר מועמד - נתון חסר
A120: רע"מ | B120: 1 | C120: מנסור עבאס | D120: ז | E120: חבר/ת כנסת מכהן/ת
A121: רע"מ | B121: 2 | C121: יואב סגלוביץ' | D121: ז | E121: מצטרף לרשימת רע"מ במיקום 2 - עודכן לפי בקשת המשתמש (לשעבר חבר כנסת ביש עתיד/ביחד)
A122: רע"מ | B122: 3 | C122: וליד טאהא | D122: ז | E122: חבר/ת כנסת מכהן/ת
A123: רע"מ | B123: 4 | C123: וליד אלהואשלה | D123: ז | E123: חבר/ת כנסת מכהן/ת
A124: רע"מ | B124: 5 | C124: אימאן ח'טיב יאסין | D124: נ | E124: חבר/ת כנסת מכהן/ת
A125: רע"מ | B125: 6 | C125: יאסר חוג'יראת | D125: ז | E125: חבר/ת כנסת מכהן/ת (מושב חמישי לא ודאי)
A126: ש"ס | B126: 1 | C126: אריה דרעי | D126: ז | E126: חבר/ת כנסת מכהן/ת (מפלגה חד-מגדרית באופן היסטורי)
A127: ש"ס | B127: 2 | C127: יעקב מרגי | D127: ז | E127: חבר/ת כנסת מכהן/ת (מפלגה חד-מגדרית באופן היסטורי)
A128: ש"ס | B128: 3 | C128: יואב בן צור | D128: ז | E128: חבר/ת כנסת מכהן/ת (מפלגה חד-מגדרית באופן היסטורי)
A129: ש"ס | B129: 4 | C129: מיכאל מלכיאלי | D129: ז | E129: חבר/ת כנסת מכהן/ת (מפלגה חד-מגדרית באופן היסטורי)
A130: ש"ס | B130: 5 | C130: חיים ביטון | D130: ז | E130: חבר/ת כנסת מכהן/ת (מפלגה חד-מגדרית באופן היסטורי)
A131: ש"ס | B131: 6 | C131: משה ארבל | D131: ז | E131: חבר/ת כנסת מכהן/ת (מפלגה חד-מגדרית באופן היסטורי)
... A133: ש"ס | B133: 8 | C133: משה אבוטבול | D133: ז | E133: חבר/ת כנסת מכהן/ת (מפלגה חד-מגדרית באופן היסטורי)

Sheet חישוב 2026
A1: מפלגה | B1: מנדטים צפויים | C1: כמות נשים צפויה | D1: כמות גברים צפויה | E1: אחוז נשים צפוי | F1: הערות | G1: מנדטים נוכחיים (כנסת 25) | H1: נשים נוכחיות | I1: אחוז נשים נוכחי
A2: הליכוד | B2: =INDEX('סקר 2026'!$D:$D,MATCH(A2,'סקר 2026'!$A:$A,0)) | C2: =COUNTIFS('מועמדים 2026'!$A:$A,A2,'מועמדים 2026'!$D:$D,"נ",'מועמדים 2026'!$B:$B,"<="&B2) | D2: =COUNTIFS('מועמדים 2026'!$A:$A,A2,'מועמדים 2026'!$D:$D,"ז",'מועמדים 2026'!$B:$B,"<="&B2) | E2: =IF(B2=0,0,C2/B2) | F2: רשימה מבוססת על סדר הכנסת ה-25 (בחירות 2022, kan.org.il); הרשימה הרשמית לבחירות 2026 טרם פורסמה | G2: 32 | H2: 7 | I2: =IF(G2=0,0,H2/G2)
A3: ישר! | B3: =INDEX('סקר 2026'!$D:$D,MATCH(A3,'סקר 2026'!$A:$A,0)) | C3: =COUNTIFS('מועמדים 2026'!$A:$A,A3,'מועמדים 2026'!$D:$D,"נ",'מועמדים 2026'!$B:$B,"<="&B3) | D3: =COUNTIFS('מועמדים 2026'!$A:$A,A3,'מועמדים 2026'!$D:$D,"ז",'מועמדים 2026'!$B:$B,"<="&B3) | E3: =IF(B3=0,0,C3/B3) | F3: רשימה עודכנה מהאתר הרשמי (yasharwitheisenkot.com/team-member); רק 11 מתוך כ-23 המנדטים הצפויים משויכים לשמות ידועים - הנתון הוא רף תחתון (מינימום) | G3: 0 | H3: 0 | I3: =IF(G3=0,0,H3/G3)
A4: ביחד (בנט-לפיד) | B4: =INDEX('סקר 2026'!$D:$D,MATCH(A4,'סקר 2026'!$A:$A,0)) | C4: =COUNTIFS('מועמדים 2026'!$A:$A,A4,'מועמדים 2026'!$D:$D,"נ",'מועמדים 2026'!$B:$B,"<="&B4) | D4: =COUNTIFS('מועמדים 2026'!$A:$A,A4,'מועמדים 2026'!$D:$D,"ז",'מועמדים 2026'!$B:$B,"<="&B4) | E4: =IF(B4=0,0,C4/B4) | F4: עודכן: כלל 24 חברי הכנסת המכהנים הנוכחיים של יש עתיד (ערוץ כנסת). בתוך 14 המנדטים הצפויים שובצו לפיד + 5 חכ"ים נוספים של יש עתיד (לפי יחס משוער של כ-40-45% ללפיד, בהתאם למחקר קודם), ו-7 שמות נוספים מצד בנט שדווחו בתקשורת. סדר הרשימה בפועל טרם פורסם. | יואב סגלוביץ' הוסר מהרשימה (עבר לרע"מ) | G4: 24 | H4: 9 | I4: =IF(G4=0,0,H4/G4)
A5: הדמוקרטים | B5: =INDEX('סקר 2026'!$D:$D,MATCH(A5,'סקר 2026'!$A:$A,0)) | C5: =COUNTIFS('מועמדים 2026'!$A:$A,A5,'מועמדים 2026'!$D:$D,"נ",'מועמדים 2026'!$B:$B,"<="&B5) | D5: =COUNTIFS('מועמדים 2026'!$A:$A,A5,'מועמדים 2026'!$D:$D,"ז",'מועמדים 2026'!$B:$B,"<="&B5) | E5: =IF(B5=0,0,C5/B5) | F5: רשימה סופית רשמית | G5: 4 | H5: 3 | I5: =IF(G5=0,0,H5/G5)
A6: ישראל ביתנו | B6: =INDEX('סקר 2026'!$D:$D,MATCH(A6,'סקר 2026'!$A:$A,0)) | C6: =COUNTIFS('מועמדים 2026'!$A:$A,A6,'מועמדים 2026'!$D:$D,"נ",'מועמדים 2026'!$B:$B,"<="&B6) | D6: =COUNTIFS('מועמדים 2026'!$A:$A,A6,'מועמדים 2026'!$D:$D,"ז",'מועמדים 2026'!$B:$B,"<="&B6) | E6: =IF(B6=0,0,C6/B6) | F6: 3 המקומות האחרונים (7-9) משוערים על סמך שמות שדווחו בתקשורת | G6: 6 | H6: 2 | I6: =IF(G6=0,0,H6/G6)
A7: ש"ס | B7: =INDEX('סקר 2026'!$D:$D,MATCH(A7,'סקר 2026'!$A:$A,0)) | C7: =COUNTIFS('מועמדים 2026'!$A:$A,A7,'מועמדים 2026'!$D:$D,"נ",'מועמדים 2026'!$B:$B,"<="&B7) | D7: =COUNTIFS('מועמדים 2026'!$A:$A,A7,'מועמדים 2026'!$D:$D,"ז",'מועמדים 2026'!$B:$B,"<="&B7) | E7: =IF(B7=0,0,C7/B7) | F7: מפלגה חד-מגדרית באופן היסטורי | G7: 11 | H7: 0 | I7: =IF(G7=0,0,H7/G7)
A8: עוצמה יהודית | B8: =INDEX('סקר 2026'!$D:$D,MATCH(A8,'סקר 2026'!$A:$A,0)) | C8: =COUNTIFS('מועמדים 2026'!$A:$A,A8,'מועמדים 2026'!$D:$D,"נ",'מועמדים 2026'!$B:$B,"<="&B8) | D8: =COUNTIFS('מועמדים 2026'!$A:$A,A8,'מועמדים 2026'!$D:$D,"ז",'מועמדים 2026'!$B:$B,"<="&B8) | E8: =IF(B8=0,0,C8/B8) | F8: מיקום 8 לא אותר - חסר בנתונים | G8: 6 | H8: 1 | I8: =IF(G8=0,0,H8/G8)
A9: יהדות התורה | B9: =INDEX('סקר 2026'!$D:$D,MATCH(A9,'סקר 2026'!$A:$A,0)) | C9: =COUNTIFS('מועמדים 2026'!$A:$A,A9,'מועמדים 2026'!$D:$D,"נ",'מועמדים 2026'!$B:$B,"<="&B9) | D9: =COUNTIFS('מועמדים 2026'!$A:$A,A9,'מועמדים 2026'!$D:$D,"ז",'מועמדים 2026'!$B:$B,"<="&B9) | E9: =IF(B9=0,0,C9/B9) | F9: מפלגה חד-מגדרית באופן היסטורי; מיקום 8 משוער | G9: 7 | H9: 0 | I9: =IF(G9=0,0,H9/G9)
A10: חדש תע"ל | B10: =INDEX('סקר 2026'!$D:$D,MATCH(A10,'סקר 2026'!$A:$A,0)) | C10: =COUNTIFS('מועמדים 2026'!$A:$A,A10,'מועמדים 2026'!$D:$D,"נ",'מועמדים 2026'!$B:$B,"<="&B10) | D10: =COUNTIFS('מועמדים 2026'!$A:$A,A10,'מועמדים 2026'!$D:$D,"ז",'מועמדים 2026'!$B:$B,"<="&B10) | E10: =IF(B10=0,0,C10/B10) | F10: רשימת חד"ש הרשמית מאתר המפלגה (hadash.org.il/list); אחמד טיבי (תע"ל) הוכנס במיקום 2 לפי בקשת המשתמש; איאס נאטור (מיקום 7) מחוץ לטווח 6 המנדטים | G10: 5 | H10: 1 | I10: =IF(G10=0,0,H10/G10)
A11: הציונות הדתית | B11: =INDEX('סקר 2026'!$D:$D,MATCH(A11,'סקר 2026'!$A:$A,0)) | C11: =COUNTIFS('מועמדים 2026'!$A:$A,A11,'מועמדים 2026'!$D:$D,"נ",'מועמדים 2026'!$B:$B,"<="&B11) | D11: =COUNTIFS('מועמדים 2026'!$A:$A,A11,'מועמדים 2026'!$D:$D,"ז",'מועמדים 2026'!$B:$B,"<="&B11) | E11: =IF(B11=0,0,C11/B11) | F11: פריימריז צפוי 26.7.2026 - הסדר עשוי להשתנות | G11: 7 | H11: 2 | I11: =IF(G11=0,0,H11/G11)
A12: רע"מ | B12: =INDEX('סקר 2026'!$D:$D,MATCH(A12,'סקר 2026'!$A:$A,0)) | C12: =COUNTIFS('מועמדים 2026'!$A:$A,A12,'מועמדים 2026'!$D:$D,"נ",'מועמדים 2026'!$B:$B,"<="&B12) | D12: =COUNTIFS('מועמדים 2026'!$A:$A,A12,'מועמדים 2026'!$D:$D,"ז",'מועמדים 2026'!$B:$B,"<="&B12) | E12: =IF(B12=0,0,C12/B12) | F12: מושב 6 (יאסר חוג'יראת) לא ודאי; יואב סגלוביץ' נוסף במיקום 2 לפי בקשת המשתמש (הצטרפות מיש עתיד/ביחד) | G12: 5 | H12: 1 | I12: =IF(G12=0,0,H12/G12)
A13: טרופר-הנדל | B13: =INDEX('סקר 2026'!$D:$D,MATCH(A13,'סקר 2026'!$A:$A,0)) | C13: =COUNTIFS('מועמדים 2026'!$A:$A,A13,'מועמדים 2026'!$D:$D,"נ",'מועמדים 2026'!$B:$B,"<="&B13) | D13: =COUNTIFS('מועמדים 2026'!$A:$A,A13,'מועמדים 2026'!$D:$D,"ז",'מועמדים 2026'!$B:$B,"<="&B13) | E13: =IF(B13=0,0,C13/B13) | F13: 0 מנדטים חזויים (מתחת לסף שנקבע) - לא נספר
A14: כחול לבן | B14: =INDEX('סקר 2026'!$D:$D,MATCH(A14,'סקר 2026'!$A:$A,0)) | C14: =COUNTIFS('מועמדים 2026'!$A:$A,A14,'מועמדים 2026'!$D:$D,"נ",'מועמדים 2026'!$B:$B,"<="&B14) | D14: =COUNTIFS('מועמדים 2026'!$A:$A,A14,'מועמדים 2026'!$D:$D,"ז",'מועמדים 2026'!$B:$B,"<="&B14) | E14: =IF(B14=0,0,C14/B14) | F14: 0 מנדטים חזויים (מתחת לסף שנקבע) - לא נספר | G14: 8 | H14: 2 | I14: =IF(G14=0,0,H14/G14)
A15: בל"ד | B15: =INDEX('סקר 2026'!$D:$D,MATCH(A15,'סקר 2026'!$A:$A,0)) | C15: =COUNTIFS('מועמדים 2026'!$A:$A,A15,'מועמדים 2026'!$D:$D,"נ",'מועמדים 2026'!$B:$B,"<="&B15) | D15: =COUNTIFS('מועמדים 2026'!$A:$A,A15,'מועמדים 2026'!$D:$D,"ז",'מועמדים 2026'!$B:$B,"<="&B15) | E15: =IF(B15=0,0,C15/B15) | F15: 0 מנדטים חזויים (מתחת לסף שנקבע) - לא נספר
A16: רשימה ערבית מאוחדת | B16: =INDEX('סקר 2026'!$D:$D,MATCH(A16,'סקר 2026'!$A:$A,0)) | C16: =COUNTIFS('מועמדים 2026'!$A:$A,A16,'מועמדים 2026'!$D:$D,"נ",'מועמדים 2026'!$B:$B,"<="&B16) | D16: =COUNTIFS('מועמדים 2026'!$A:$A,A16,'מועמדים 2026'!$D:$D,"ז",'מועמדים 2026'!$B:$B,"<="&B16) | E16: =IF(B16=0,0,C16/B16) | F16: 0 מנדטים חזויים (מתחת לסף שנקבע) - לא נספר
A17: סה"כ | B17: =SUM(B2:B16) | C17: =SUM(C2:C16) | D17: =SUM(D2:D16) | E17: =IF(B17=0,0,C17/B17) | G17: =SUM(G2:G16) | H17: =SUM(H2:H16) | I17: =IF(G17=0,0,H17/G17)

Sheet סקרים לפי ערוץ
A1: כלי תקשורת | B1: תאריך הסקר | C1: סוקר | D1: מספר משיבים | E1: הליכוד | F1: יהדות התורה | G1: ש"ס | H1: כחול לבן | I1: חדש תע"ל | J1: ישראל ביתנו | K1: הדמוקרטים | L1: הציונות הדתית | M1: רע"מ | N1: עוצמה יהודית | O1: ביחד (בנט-לפיד) | P1: ישר!
A2: מעריב | B2: 2026-07-31 | C2: מנחם לזר | D2: 501 | E2: 22 | F2: 8 | G2: 7 | H2: 0 | I2: 5 | J2: 10 | K2: 9 | L2: 5 | M2: 5 | N2: 7 | O2: 15 | P2: 23
A3: זמן ישראל | B3: 2026-07-30 | C3: יוסי טאטיקה | D3: 500 | E3: 20 | F3: 8 | G3: 8 | H3: 4 | I3: 6 | J3: 10 | K3: 8 | L3: 6 | M3: 5 | N3: 7 | O3: 13 | P3: 21
A4: חדשות 13 | B4: 2026-07-29 | C4: המדד | D4: 956 | E4: 23 | F4: 9 | G4: 7 | H4: 0 | I4: 4 | J4: 10 | K4: 9 | L4: 4 | M4: 5 | N4: 8 | O4: 13 | P4: 23
A5: ערוץ 14 | B5: 2026-07-29 | C5: שלמה פילבר | D5: 539 | E5: 32 | F5: 8 | G5: 10 | H5: 0 | I5: 6 | J5: 8 | K5: 10 | L5: 5 | M5: 5 | N5: 7 | O5: 7 | P5: 22
A6: i24 news | B6: 2026-07-27 | C6: צוריאל שרון | D6: 525 | E6: 29 | F6: 8 | G6: 9 | H6: 0 | I6: 7 | J6: 9 | K6: 10 | L6: 5 | M6: 5 | N6: 8 | O6: 9 | P6: 21
A7: חדשות 12 | B7: 2026-07-27 | C7: מנו גבע | D7: 509 | E7: 22 | F7: 8 | G7: 8 | H7: 0 | I7: 5 | J7: 9 | K7: 10 | L7: 4 | M7: 5 | N7: 8 | O7: 14 | P7: 23
A8: כאן חדשות | B8: 2026-07-26 | C8: דודי חסיד | D8: 550 | E8: 22 | F8: 8 | G8: 8 | H8: 0 | I8: 5 | J8: 9 | K8: 10 | L8: 5 | M8: 5 | N8: 9 | O8: 14 | P8: 21
A9: ישראל היום | B9: 2026-07-23 | C9: דודי חסיד | D9: 500 | E9: 23 | F9: 8 | G9: 8 | H9: 0 | I9: 5 | J9: 9 | K9: 10 | L9: 5 | M9: 6 | N9: 9 | O9: 14 | P9: 23
A10: וואלה | B10: 2026-04-27 | C10: מנחם לזר | D10: 500 | E10: 28 | F10: 7 | G10: 8 | H10: 0 | I10: 5 | J10: 8 | K10: 9 | L10: 0 | M10: 5 | N10: 8 | O10: 27 | P10: 15

Sheet חישוב לפי ערוץ
A1: כלי תקשורת | B1: תאריך הסקר | C1: מפלגה | D1: מנדטים | E1: כמות נשים צפויה | F1: כמות גברים צפויה | G1: אחוז נשים צפוי | H1: מועמדים ידועים (סה"כ) | I1: הערה
A2: מעריב | B2: =INDEX('סקרים לפי ערוץ'!$B:$B,MATCH($A2,'סקרים לפי ערוץ'!$A:$A,0)) | C2: הליכוד | D2: =INDEX('סקרים לפי ערוץ'!E:E,MATCH($A2,'סקרים לפי ערוץ'!$A:$A,0)) | E2: =COUNTIFS('מועמדים 2026'!$A:$A,$C2,'מועמדים 2026'!$D:$D,"נ",'מועמדים 2026'!$B:$B,"<="&$D2) | F2: =COUNTIFS('מועמדים 2026'!$A:$A,$C2,'מועמדים 2026'!$D:$D,"ז",'מועמדים 2026'!$B:$B,"<="&$D2) | G2: =IF($D2=0,0,$E2/$D2) | H2: =COUNTIFS('מועמדים 2026'!$A:$A,$C2) | I2: =IF(AND($D2>0,$H2=0),"אין נתוני מועמדים לחישוב","")
A3: מעריב | B3: =INDEX('סקרים לפי ערוץ'!$B:$B,MATCH($A3,'סקרים לפי ערוץ'!$A:$A,0)) | C3: יהדות התורה | D3: =INDEX('סקרים לפי ערוץ'!F:F,MATCH($A3,'סקרים לפי ערוץ'!$A:$A,0)) | E3: =COUNTIFS('מועמדים 2026'!$A:$A,$C3,'מועמדים 2026'!$D:$D,"נ",'מועמדים 2026'!$B:$B,"<="&$D3) | F3: =COUNTIFS('מועמדים 2026'!$A:$A,$C3,'מועמדים 2026'!$D:$D,"ז",'מועמדים 2026'!$B:$B,"<="&$D3) | G3: =IF($D3=0,0,$E3/$D3) | H3: =COUNTIFS('מועמדים 2026'!$A:$A,$C3) | I3: =IF(AND($D3>0,$H3=0),"אין נתוני מועמדים לחישוב","")
A4: מעריב | B4: =INDEX('סקרים לפי ערוץ'!$B:$B,MATCH($A4,'סקרים לפי ערוץ'!$A:$A,0)) | C4: ש"ס | D4: =INDEX('סקרים לפי ערוץ'!G:G,MATCH($A4,'סקרים לפי ערוץ'!$A:$A,0)) | E4: =COUNTIFS('מועמדים 2026'!$A:$A,$C4,'מועמדים 2026'!$D:$D,"נ",'מועמדים 2026'!$B:$B,"<="&$D4) | F4: =COUNTIFS('מועמדים 2026'!$A:$A,$C4,'מועמדים 2026'!$D:$D,"ז",'מועמדים 2026'!$B:$B,"<="&$D4) | G4: =IF($D4=0,0,$E4/$D4) | H4: =COUNTIFS('מועמדים 2026'!$A:$A,$C4) | I4: =IF(AND($D4>0,$H4=0),"אין נתוני מועמדים לחישוב","")
A5: מעריב | B5: =INDEX('סקרים לפי ערוץ'!$B:$B,MATCH($A5,'סקרים לפי ערוץ'!$A:$A,0)) | C5: כחול לבן | D5: =INDEX('סקרים לפי ערוץ'!H:H,MATCH($A5,'סקרים לפי ערוץ'!$A:$A,0)) | E5: =COUNTIFS('מועמדים 2026'!$A:$A,$C5,'מועמדים 2026'!$D:$D,"נ",'מועמדים 2026'!$B:$B,"<="&$D5) | F5: =COUNTIFS('מועמדים 2026'!$A:$A,$C5,'מועמדים 2026'!$D:$D,"ז",'מועמדים 2026'!$B:$B,"<="&$D5) | G5: =IF($D5=0,0,$E5/$D5) | H5: =COUNTIFS('מועמדים 2026'!$A:$A,$C5) | I5: =IF(AND($D5>0,$H5=0),"אין נתוני מועמדים לחישוב","")
A6: מעריב | B6: =INDEX('סקרים לפי ערוץ'!$B:$B,MATCH($A6,'סקרים לפי ערוץ'!$A:$A,0)) | C6: חדש תע"ל | D6: =INDEX('סקרים לפי ערוץ'!I:I,MATCH($A6,'סקרים לפי ערוץ'!$A:$A,0)) | E6: =COUNTIFS('מועמדים 2026'!$A:$A,$C6,'מועמדים 2026'!$D:$D,"נ",'מועמדים 2026'!$B:$B,"<="&$D6) | F6: =COUNTIFS('מועמדים 2026'!$A:$A,$C6,'מועמדים 2026'!$D:$D,"ז",'מועמדים 2026'!$B:$B,"<="&$D6) | G6: =IF($D6=0,0,$E6/$D6) | H6: =COUNTIFS('מועמדים 2026'!$A:$A,$C6) | I6: =IF(AND($D6>0,$H6=0),"אין נתוני מועמדים לחישוב","")
A7: מעריב | B7: =INDEX('סקרים לפי ערוץ'!$B:$B,MATCH($A7,'סקרים לפי ערוץ'!$A:$A,0)) | C7: ישראל ביתנו | D7: =INDEX('סקרים לפי ערוץ'!J:J,MATCH($A7,'סקרים לפי ערוץ'!$A:$A,0)) | E7: =COUNTIFS('מועמדים 2026'!$A:$A,$C7,'מועמדים 2026'!$D:$D,"נ",'מועמדים 2026'!$B:$B,"<="&$D7) | F7: =COUNTIFS('מועמדים 2026'!$A:$A,$C7,'מועמדים 2026'!$D:$D,"ז",'מועמדים 2026'!$B:$B,"<="&$D7) | G7: =IF($D7=0,0,$E7/$D7) | H7: =COUNTIFS('מועמדים 2026'!$A:$A,$C7) | I7: =IF(AND($D7>0,$H7=0),"אין נתוני מועמדים לחישוב","")
A8: מעריב | B8: =INDEX('סקרים לפי ערוץ'!$B:$B,MATCH($A8,'סקרים לפי ערוץ'!$A:$A,0)) | C8: הדמוקרטים | D8: =INDEX('סקרים לפי ערוץ'!K:K,MATCH($A8,'סקרים לפי ערוץ'!$A:$A,0)) | E8: =COUNTIFS('מועמדים 2026'!$A:$A,$C8,'מועמדים 2026'!$D:$D,"נ",'מועמדים 2026'!$B:$B,"<="&$D8) | F8: =COUNTIFS('מועמדים 2026'!$A:$A,$C8,'מועמדים 2026'!$D:$D,"ז",'מועמדים 2026'!$B:$B,"<="&$D8) | G8: =IF($D8=0,0,$E8/$D8) | H8: =COUNTIFS('מועמדים 2026'!$A:$A,$C8) | I8: =IF(AND($D8>0,$H8=0),"אין נתוני מועמדים לחישוב","")
A9: מעריב | B9: =INDEX('סקרים לפי ערוץ'!$B:$B,MATCH($A9,'סקרים לפי ערוץ'!$A:$A,0)) | C9: הציונות הדתית | D9: =INDEX('סקרים לפי ערוץ'!L:L,MATCH($A9,'סקרים לפי ערוץ'!$A:$A,0)) | E9: =COUNTIFS('מועמדים 2026'!$A:$A,$C9,'מועמדים 2026'!$D:$D,"נ",'מועמדים 2026'!$B:$B,"<="&$D9) | F9: =COUNTIFS('מועמדים 2026'!$A:$A,$C9,'מועמדים 2026'!$D:$D,"ז",'מועמדים 2026'!$B:$B,"<="&$D9) | G9: =IF($D9=0,0,$E9/$D9) | H9: =COUNTIFS('מועמדים 2026'!$A:$A,$C9) | I9: =IF(AND($D9>0,$H9=0),"אין נתוני מועמדים לחישוב","")
A10: מעריב | B10: =INDEX('סקרים לפי ערוץ'!$B:$B,MATCH($A10,'סקרים לפי ערוץ'!$A:$A,0)) | C10: רע"מ | D10: =INDEX('סקרים לפי ערוץ'!M:M,MATCH($A10,'סקרים לפי ערוץ'!$A:$A,0)) | E10: =COUNTIFS('מועמדים 2026'!$A:$A,$C10,'מועמדים 2026'!$D:$D,"נ",'מועמדים 2026'!$B:$B,"<="&$D10) | F10: =COUNTIFS('מועמדים 2026'!$A:$A,$C10,'מועמדים 2026'!$D:$D,"ז",'מועמדים 2026'!$B:$B,"<="&$D10) | G10: =IF($D10=0,0,$E10/$D10) | H10: =COUNTIFS('מועמדים 2026'!$A:$A,$C10) | I10: =IF(AND($D10>0,$H10=0),"אין נתוני מועמדים לחישוב","")
A11: מעריב | B11: =INDEX('סקרים לפי ערוץ'!$B:$B,MATCH($A11,'סקרים לפי ערוץ'!$A:$A,0)) | C11: עוצמה יהודית | D11: =INDEX('סקרים לפי ערוץ'!N:N,MATCH($A11,'סקרים לפי ערוץ'!$A:$A,0)) | E11: =COUNTIFS('מועמדים 2026'!$A:$A,$C11,'מועמדים 2026'!$D:$D,"נ",'מועמדים 2026'!$B:$B,"<="&$D11) | F11: =COUNTIFS('מועמדים 2026'!$A:$A,$C11,'מועמדים 2026'!$D:$D,"ז",'מועמדים 2026'!$B:$B,"<="&$D11) | G11: =IF($D11=0,0,$E11/$D11) | H11: =COUNTIFS('מועמדים 2026'!$A:$A,$C11) | I11: =IF(AND($D11>0,$H11=0),"אין נתוני מועמדים לחישוב","")
A12: מעריב | B12: =INDEX('סקרים לפי ערוץ'!$B:$B,MATCH($A12,'סקרים לפי ערוץ'!$A:$A,0)) | C12: ביחד (בנט-לפיד) | D12: =INDEX('סקרים לפי ערוץ'!O:O,MATCH($A12,'סקרים לפי ערוץ'!$A:$A,0)) | E12: =COUNTIFS('מועמדים 2026'!$A:$A,$C12,'מועמדים 2026'!$D:$D,"נ",'מועמדים 2026'!$B:$B,"<="&$D12) | F12: =COUNTIFS('מועמדים 2026'!$A:$A,$C12,'מועמדים 2026'!$D:$D,"ז",'מועמדים 2026'!$B:$B,"<="&$D12) | G12: =IF($D12=0,0,$E12/$D12) | H12: =COUNTIFS('מועמדים 2026'!$A:$A,$C12) | I12: =IF(AND($D12>0,$H12=0),"אין נתוני מועמדים לחישוב","")
A13: מעריב | B13: =INDEX('סקרים לפי ערוץ'!$B:$B,MATCH($A13,'סקרים לפי ערוץ'!$A:$A,0)) | C13: ישר! | D13: =INDEX('סקרים לפי ערוץ'!P:P,MATCH($A13,'סקרים לפי ערוץ'!$A:$A,0)) | E13: =COUNTIFS('מועמדים 2026'!$A:$A,$C13,'מועמדים 2026'!$D:$D,"נ",'מועמדים 2026'!$B:$B,"<="&$D13) | F13: =COUNTIFS('מועמדים 2026'!$A:$A,$C13,'מועמדים 2026'!$D:$D,"ז",'מועמדים 2026'!$B:$B,"<="&$D13) | G13: =IF($D13=0,0,$E13/$D13) | H13: =COUNTIFS('מועמדים 2026'!$A:$A,$C13) | I13: =IF(AND($D13>0,$H13=0),"אין נתוני מועמדים לחישוב","")
A14: זמן ישראל | B14: =INDEX('סקרים לפי ערוץ'!$B:$B,MATCH($A14,'סקרים לפי ערוץ'!$A:$A,0)) | C14: הליכוד | D14: =INDEX('סקרים לפי ערוץ'!E:E,MATCH($A14,'סקרים לפי ערוץ'!$A:$A,0)) | E14: =COUNTIFS('מועמדים 2026'!$A:$A,$C14,'מועמדים 2026'!$D:$D,"נ",'מועמדים 2026'!$B:$B,"<="&$D14) | F14: =COUNTIFS('מועמדים 2026'!$A:$A,$C14,'מועמדים 2026'!$D:$D,"ז",'מועמדים 2026'!$B:$B,"<="&$D14) | G14: =IF($D14=0,0,$E14/$D14) | H14: =COUNTIFS('מועמדים 2026'!$A:$A,$C14) | I14: =IF(AND($D14>0,$H14=0),"אין נתוני מועמדים לחישוב","")
A15: זמן ישראל | B15: =INDEX('סקרים לפי ערוץ'!$B:$B,MATCH($A15,'סקרים לפי ערוץ'!$A:$A,0)) | C15: יהדות התורה | D15: =INDEX('סקרים לפי ערוץ'!F:F,MATCH($A15,'סקרים לפי ערוץ'!$A:$A,0)) | E15: =COUNTIFS('מועמדים 2026'!$A:$A,$C15,'מועמדים 2026'!$D:$D,"נ",'מועמדים 2026'!$B:$B,"<="&$D15) | F15: =COUNTIFS('מועמדים 2026'!$A:$A,$C15,'מועמדים 2026'!$D:$D,"ז",'מועמדים 2026'!$B:$B,"<="&$D15) | G15: =IF($D15=0,0,$E15/$D15) | H15: =COUNTIFS('מועמדים 2026'!$A:$A,$C15) | I15: =IF(AND($D15>0,$H15=0),"אין נתוני מועמדים לחישוב","")
A16: זמן ישראל | B16: =INDEX('סקרים לפי ערוץ'!$B:$B,MATCH($A16,'סקרים לפי ערוץ'!$A:$A,0)) | C16: ש"ס | D16: =INDEX('סקרים לפי ערוץ'!G:G,MATCH($A16,'סקרים לפי ערוץ'!$A:$A,0)) | E16: =COUNTIFS('מועמדים 2026'!$A:$A,$C16,'מועמדים 2026'!$D:$D,"נ",'מועמדים 2026'!$B:$B,"<="&$D16) | F16: =COUNTIFS('מועמדים 2026'!$A:$A,$C16,'מועמדים 2026'!$D:$D,"ז",'מועמדים 2026'!$B:$B,"<="&$D16) | G16: =IF($D16=0,0,$E16/$D16) | H16: =COUNTIFS('מועמדים 2026'!$A:$A,$C16) | I16: =IF(AND($D16>0,$H16=0),"אין נתוני מועמדים לחישוב","")
A17: זמן ישראל | B17: =INDEX('סקרים לפי ערוץ'!$B:$B,MATCH($A17,'סקרים לפי ערוץ'!$A:$A,0)) | C17: כחול לבן | D17: =INDEX('סקרים לפי ערוץ'!H:H,MATCH($A17,'סקרים לפי ערוץ'!$A:$A,0)) | E17: =COUNTIFS('מועמדים 2026'!$A:$A,$C17,'מועמדים 2026'!$D:$D,"נ",'מועמדים 2026'!$B:$B,"<="&$D17) | F17: =COUNTIFS('מועמדים 2026'!$A:$A,$C17,'מועמדים 2026'!$D:$D,"ז",'מועמדים 2026'!$B:$B,"<="&$D17) | G17: =IF($D17=0,0,$E17/$D17) | H17: =COUNTIFS('מועמדים 2026'!$A:$A,$C17) | I17: =IF(AND($D17>0,$H17=0),"אין נתוני מועמדים לחישוב","")
A18: זמן ישראל | B18: =INDEX('סקרים לפי ערוץ'!$B:$B,MATCH($A18,'סקרים לפי ערוץ'!$A:$A,0)) | C18: חדש תע"ל | D18: =INDEX('סקרים לפי ערוץ'!I:I,MATCH($A18,'סקרים לפי ערוץ'!$A:$A,0)) | E18: =COUNTIFS('מועמדים 2026'!$A:$A,$C18,'מועמדים 2026'!$D:$D,"נ",'מועמדים 2026'!$B:$B,"<="&$D18) | F18: =COUNTIFS('מועמדים 2026'!$A:$A,$C18,'מועמדים 2026'!$D:$D,"ז",'מועמדים 2026'!$B:$B,"<="&$D18) | G18: =IF($D18=0,0,$E18/$D18) | H18: =COUNTIFS('מועמדים 2026'!$A:$A,$C18) | I18: =IF(AND($D18>0,$H18=0),"אין נתוני מועמדים לחישוב","")
A19: זמן ישראל | B19: =INDEX('סקרים לפי ערוץ'!$B:$B,MATCH($A19,'סקרים לפי ערוץ'!$A:$A,0)) | C19: ישראל ביתנו | D19: =INDEX('סקרים לפי ערוץ'!J:J,MATCH($A19,'סקרים לפי ערוץ'!$A:$A,0)) | E19: =COUNTIFS('מועמדים 2026'!$A:$A,$C19,'מועמדים 2026'!$D:$D,"נ",'מועמדים 2026'!$B:$B,"<="&$D19) | F19: =COUNTIFS('מועמדים 2026'!$A:$A,$C19,'מועמדים 2026'!$D:$D,"ז",'מועמדים 2026'!$B:$B,"<="&$D19) | G19: =IF($D19=0,0,$E19/$D19) | H19: =COUNTIFS('מועמדים 2026'!$A:$A,$C19) | I19: =IF(AND($D19>0,$H19=0),"אין נתוני מועמדים לחישוב","")
A20: זמן ישראל | B20: =INDEX('סקרים לפי ערוץ'!$B:$B,MATCH($A20,'סקרים לפי ערוץ'!$A:$A,0)) | C20: הדמוקרטים | D20: =INDEX('סקרים לפי ערוץ'!K:K,MATCH($A20,'סקרים לפי ערוץ'!$A:$A,0)) | E20: =COUNTIFS('מועמדים 2026'!$A:$A,$C20,'מועמדים 2026'!$D:$D,"נ",'מועמדים 2026'!$B:$B,"<="&$D20) | F20: =COUNTIFS('מועמדים 2026'!$A:$A,$C20,'מועמדים 2026'!$D:$D,"ז",'מועמדים 2026'!$B:$B,"<="&$D20) | G20: =IF($D20=0,0,$E20/$D20) | H20: =COUNTIFS('מועמדים 2026'!$A:$A,$C20) | I20: =IF(AND($D20>0,$H20=0),"אין נתוני מועמדים לחישוב","")
A21: זמן ישראל | B21: =INDEX('סקרים לפי ערוץ'!$B:$B,MATCH($A21,'סקרים לפי ערוץ'!$A:$A,0)) | C21: הציונות הדתית | D21: =INDEX('סקרים לפי ערוץ'!L:L,MATCH($A21,'סקרים לפי ערוץ'!$A:$A,0)) | E21: =COUNTIFS('מועמדים 2026'!$A:$A,$C21,'מועמדים 2026'!$D:$D,"נ",'מועמדים 2026'!$B:$B,"<="&$D21) | F21: =COUNTIFS('מועמדים 2026'!$A:$A,$C21,'מועמדים 2026'!$D:$D,"ז",'מועמדים 2026'!$B:$B,"<="&$D21) | G21: =IF($D21=0,0,$E21/$D21) | H21: =COUNTIFS('מועמדים 2026'!$A:$A,$C21) | I21: =IF(AND($D21>0,$H21=0),"אין נתוני מועמדים לחישוב","")
A22: זמן ישראל | B22: =INDEX('סקרים לפי ערוץ'!$B:$B,MATCH($A22,'סקרים לפי ערוץ'!$A:$A,0)) | C22: רע"מ | D22: =INDEX('סקרים לפי ערוץ'!M:M,MATCH($A22,'סקרים לפי ערוץ'!$A:$A,0)) | E22: =COUNTIFS('מועמדים 2026'!$A:$A,$C22,'מועמדים 2026'!$D:$D,"נ",'מועמדים 2026'!$B:$B,"<="&$D22) | F22: =COUNTIFS('מועמדים 2026'!$A:$A,$C22,'מועמדים 2026'!$D:$D,"ז",'מועמדים 2026'!$B:$B,"<="&$D22) | G22: =IF($D22=0,0,$E22/$D22) | H22: =COUNTIFS('מועמדים 2026'!$A:$A,$C22) | I22: =IF(AND($D22>0,$H22=0),"אין נתוני מועמדים לחישוב","")
A23: זמן ישראל | B23: =INDEX('סקרים לפי ערוץ'!$B:$B,MATCH($A23,'סקרים לפי ערוץ'!$A:$A,0)) | C23: עוצמה יהודית | D23: =INDEX('סקרים לפי ערוץ'!N:N,MATCH($A23,'סקרים לפי ערוץ'!$A:$A,0)) | E23: =COUNTIFS('מועמדים 2026'!$A:$A,$C23,'מועמדים 2026'!$D:$D,"נ",'מועמדים 2026'!$B:$B,"<="&$D23) | F23: =COUNTIFS('מועמדים 2026'!$A:$A,$C23,'מועמדים 2026'!$D:$D,"ז",'מועמדים 2026'!$B:$B,"<="&$D23) | G23: =IF($D23=0,0,$E23/$D23) | H23: =COUNTIFS('מועמדים 2026'!$A:$A,$C23) | I23: =IF(AND($D23>0,$H23=0),"אין נתוני מועמדים לחישוב","")
A24: זמן ישראל | B24: =INDEX('סקרים לפי ערוץ'!$B:$B,MATCH($A24,'סקרים לפי ערוץ'!$A:$A,0)) | C24: ביחד (בנט-לפיד) | D24: =INDEX('סקרים לפי ערוץ'!O:O,MATCH($A24,'סקרים לפי ערוץ'!$A:$A,0)) | E24: =COUNTIFS('מועמדים 2026'!$A:$A,$C24,'מועמדים 2026'!$D:$D,"נ",'מועמדים 2026'!$B:$B,"<="&$D24) | F24: =COUNTIFS('מועמדים 2026'!$A:$A,$C24,'מועמדים 2026'!$D:$D,"ז",'מועמדים 2026'!$B:$B,"<="&$D24) | G24: =IF($D24=0,0,$E24/$D24) | H24: =COUNTIFS('מועמדים 2026'!$A:$A,$C24) | I24: =IF(AND($D24>0,$H24=0),"אין נתוני מועמדים לחישוב","")
A25: זמן ישראל | B25: =INDEX('סקרים לפי ערוץ'!$B:$B,MATCH($A25,'סקרים לפי ערוץ'!$A:$A,0)) | C25: ישר! | D25: =INDEX('סקרים לפי ערוץ'!P:P,MATCH($A25,'סקרים לפי ערוץ'!$A:$A,0)) | E25: =COUNTIFS('מועמדים 2026'!$A:$A,$C25,'מועמדים 2026'!$D:$D,"נ",'מועמדים 2026'!$B:$B,"<="&$D25) | F25: =COUNTIFS('מועמדים 2026'!$A:$A,$C25,'מועמדים 2026'!$D:$D,"ז",'מועמדים 2026'!$B:$B,"<="&$D25) | G25: =IF($D25=0,0,$E25/$D25) | H25: =COUNTIFS('מועמדים 2026'!$A:$A,$C25) | I25: =IF(AND($D25>0,$H25=0),"אין נתוני מועמדים לחישוב","")
A26: חדשות 13 | B26: =INDEX('סקרים לפי ערוץ'!$B:$B,MATCH($A26,'סקרים לפי ערוץ'!$A:$A,0)) | C26: הליכוד | D26: =INDEX('סקרים לפי ערוץ'!E:E,MATCH($A26,'סקרים לפי ערוץ'!$A:$A,0)) | E26: =COUNTIFS('מועמדים 2026'!$A:$A,$C26,'מועמדים 2026'!$D:$D,"נ",'מועמדים 2026'!$B:$B,"<="&$D26) | F26: =COUNTIFS('מועמדים 2026'!$A:$A,$C26,'מועמדים 2026'!$D:$D,"ז",'מועמדים 2026'!$B:$B,"<="&$D26) | G26: =IF($D26=0,0,$E26/$D26) | H26: =COUNTIFS('מועמדים 2026'!$A:$A,$C26) | I26: =IF(AND($D26>0,$H26=0),"אין נתוני מועמדים לחישוב","")
A27: חדשות 13 | B27: =INDEX('סקרים לפי ערוץ'!$B:$B,MATCH($A27,'סקרים לפי ערוץ'!$A:$A,0)) | C27: יהדות התורה | D27: =INDEX('סקרים לפי ערוץ'!F:F,MATCH($A27,'סקרים לפי ערוץ'!$A:$A,0)) | E27: =COUNTIFS('מועמדים 2026'!$A:$A,$C27,'מועמדים 2026'!$D:$D,"נ",'מועמדים 2026'!$B:$B,"<="&$D27) | F27: =COUNTIFS('מועמדים 2026'!$A:$A,$C27,'מועמדים 2026'!$D:$D,"ז",'מועמדים 2026'!$B:$B,"<="&$D27) | G27: =IF($D27=0,0,$E27/$D27) | H27: =COUNTIFS('מועמדים 2026'!$A:$A,$C27) | I27: =IF(AND($D27>0,$H27=0),"אין נתוני מועמדים לחישוב","")
A28: חדשות 13 | B28: =INDEX('סקרים לפי ערוץ'!$B:$B,MATCH($A28,'סקרים לפי ערוץ'!$A:$A,0)) | C28: ש"ס | D28: =INDEX('סקרים לפי ערוץ'!G:G,MATCH($A28,'סקרים לפי ערוץ'!$A:$A,0)) | E28: =COUNTIFS('מועמדים 2026'!$A:$A,$C28,'מועמדים 2026'!$D:$D,"נ",'מועמדים 2026'!$B:$B,"<="&$D28) | F28: =COUNTIFS('מועמדים 2026'!$A:$A,$C28,'מועמדים 2026'!$D:$D,"ז",'מועמדים 2026'!$B:$B,"<="&$D28) | G28: =IF($D28=0,0,$E28/$D28) | H28: =COUNTIFS('מועמדים 2026'!$A:$A,$C28) | I28: =IF(AND($D28>0,$H28=0),"אין נתוני מועמדים לחישוב","")
A29: חדשות 13 | B29: =INDEX('סקרים לפי ערוץ'!$B:$B,MATCH($A29,'סקרים לפי ערוץ'!$A:$A,0)) | C29: כחול לבן | D29: =INDEX('סקרים לפי ערוץ'!H:H,MATCH($A29,'סקרים לפי ערוץ'!$A:$A,0)) | E29: =COUNTIFS('מועמדים 2026'!$A:$A,$C29,'מועמדים 2026'!$D:$D,"נ",'מועמדים 2026'!$B:$B,"<="&$D29) | F29: =COUNTIFS('מועמדים 2026'!$A:$A,$C29,'מועמדים 2026'!$D:$D,"ז",'מועמדים 2026'!$B:$B,"<="&$D29) | G29: =IF($D29=0,0,$E29/$D29) | H29: =COUNTIFS('מועמדים 2026'!$A:$A,$C29) | I29: =IF(AND($D29>0,$H29=0),"אין נתוני מועמדים לחישוב","")
A30: חדשות 13 | B30: =INDEX('סקרים לפי ערוץ'!$B:$B,MATCH($A30,'סקרים לפי ערוץ'!$A:$A,0)) | C30: חדש תע"ל | D30: =INDEX('סקרים לפי ערוץ'!I:I,MATCH($A30,'סקרים לפי ערוץ'!$A:$A,0)) | E30: =COUNTIFS('מועמדים 2026'!$A:$A,$C30,'מועמדים 2026'!$D:$D,"נ",'מועמדים 2026'!$B:$B,"<="&$D30) | F30: =COUNTIFS('מועמדים 2026'!$A:$A,$C30,'מועמדים 2026'!$D:$D,"ז",'מועמדים 2026'!$B:$B,"<="&$D30) | G30: =IF($D30=0,0,$E30/$D30) | H30: =COUNTIFS('מועמדים 2026'!$A:$A,$C30) | I30: =IF(AND($D30>0,$H30=0),"אין נתוני מועמדים לחישוב","")
A31: חדשות 13 | B31: =INDEX('סקרים לפי ערוץ'!$B:$B,MATCH($A31,'סקרים לפי ערוץ'!$A:$A,0)) | C31: ישראל ביתנו | D31: =INDEX('סקרים לפי ערוץ'!J:J,MATCH($A31,'סקרים לפי ערוץ'!$A:$A,0)) | E31: =COUNTIFS('מועמדים 2026'!$A:$A,$C31,'מועמדים 2026'!$D:$D,"נ",'מועמדים 2026'!$B:$B,"<="&$D31) | F31: =COUNTIFS('מועמדים 2026'!$A:$A,$C31,'מועמדים 2026'!$D:$D,"ז",'מועמדים 2026'!$B:$B,"<="&$D31) | G31: =IF($D31=0,0,$E31/$D31) | H31: =COUNTIFS('מועמדים 2026'!$A:$A,$C31) | I31: =IF(AND($D31>0,$H31=0),"אין נתוני מועמדים לחישוב","")
A32: חדשות 13 | B32: =INDEX('סקרים לפי ערוץ'!$B:$B,MATCH($A32,'סקרים לפי ערוץ'!$A:$A,0)) | C32: הדמוקרטים | D32: =INDEX('סקרים לפי ערוץ'!K:K,MATCH($A32,'סקרים לפי ערוץ'!$A:$A,0)) | E32: =COUNTIFS('מועמדים 2026'!$A:$A,$C32,'מועמדים 2026'!$D:$D,"נ",'מועמדים 2026'!$B:$B,"<="&$D32) | F32: =COUNTIFS('מועמדים 2026'!$A:$A,$C32,'מועמדים 2026'!$D:$D,"ז",'מועמדים 2026'!$B:$B,"<="&$D32) | G32: =IF($D32=0,0,$E32/$D32) | H32: =COUNTIFS('מועמדים 2026'!$A:$A,$C32) | I32: =IF(AND($D32>0,$H32=0),"אין נתוני מועמדים לחישוב","")
A33: חדשות 13 | B33: =INDEX('סקרים לפי ערוץ'!$B:$B,MATCH($A33,'סקרים לפי ערוץ'!$A:$A,0)) | C33: הציונות הדתית | D33: =INDEX('סקרים לפי ערוץ'!L:L,MATCH($A33,'סקרים לפי ערוץ'!$A:$A,0)) | E33: =COUNTIFS('מועמדים 2026'!$A:$A,$C33,'מועמדים 2026'!$D:$D,"נ",'מועמדים 2026'!$B:$B,"<="&$D33) | F33: =COUNTIFS('מועמדים 2026'!$A:$A,$C33,'מועמדים 2026'!$D:$D,"ז",'מועמדים 2026'!$B:$B,"<="&$D33) | G33: =IF($D33=0,0,$E33/$D33) | H33: =COUNTIFS('מועמדים 2026'!$A:$A,$C33) | I33: =IF(AND($D33>0,$H33=0),"אין נתוני מועמדים לחישוב","")
A34: חדשות 13 | B34: =INDEX('סקרים לפי ערוץ'!$B:$B,MATCH($A34,'סקרים לפי ערוץ'!$A:$A,0)) | C34: רע"מ | D34: =INDEX('סקרים לפי ערוץ'!M:M,MATCH($A34,'סקרים לפי ערוץ'!$A:$A,0)) | E34: =COUNTIFS('מועמדים 2026'!$A:$A,$C34,'מועמדים 2026'!$D:$D,"נ",'מועמדים 2026'!$B:$B,"<="&$D34) | F34: =COUNTIFS('מועמדים 2026'!$A:$A,$C34,'מועמדים 2026'!$D:$D,"ז",'מועמדים 2026'!$B:$B,"<="&$D34) | G34: =IF($D34=0,0,$E34/$D34) | H34: =COUNTIFS('מועמדים 2026'!$A:$A,$C34) | I34: =IF(AND($D34>0,$H34=0),"אין נתוני מועמדים לחישוב","")
A35: חדשות 13 | B35: =INDEX('סקרים לפי ערוץ'!$B:$B,MATCH($A35,'סקרים לפי ערוץ'!$A:$A,0)) | C35: עוצמה יהודית | D35: =INDEX('סקרים לפי ערוץ'!N:N,MATCH($A35,'סקרים לפי ערוץ'!$A:$A,0)) | E35: =COUNTIFS('מועמדים 2026'!$A:$A,$C35,'מועמדים 2026'!$D:$D,"נ",'מועמדים 2026'!$B:$B,"<="&$D35) | F35: =COUNTIFS('מועמדים 2026'!$A:$A,$C35,'מועמדים 2026'!$D:$D,"ז",'מועמדים 2026'!$B:$B,"<="&$D35) | G35: =IF($D35=0,0,$E35/$D35) | H35: =COUNTIFS('מועמדים 2026'!$A:$A,$C35) | I35: =IF(AND($D35>0,$H35=0),"אין נתוני מועמדים לחישוב","")
A36: חדשות 13 | B36: =INDEX('סקרים לפי ערוץ'!$B:$B,MATCH($A36,'סקרים לפי ערוץ'!$A:$A,0)) | C36: ביחד (בנט-לפיד) | D36: =INDEX('סקרים לפי ערוץ'!O:O,MATCH($A36,'סקרים לפי ערוץ'!$A:$A,0)) | E36: =COUNTIFS('מועמדים 2026'!$A:$A,$C36,'מועמדים 2026'!$D:$D,"נ",'מועמדים 2026'!$B:$B,"<="&$D36) | F36: =COUNTIFS('מועמדים 2026'!$A:$A,$C36,'מועמדים 2026'!$D:$D,"ז",'מועמדים 2026'!$B:$B,"<="&$D36) | G36: =IF($D36=0,0,$E36/$D36) | H36: =COUNTIFS('מועמדים 2026'!$A:$A,$C36) | I36: =IF(AND($D36>0,$H36=0),"אין נתוני מועמדים לחישוב","")
A37: חדשות 13 | B37: =INDEX('סקרים לפי ערוץ'!$B:$B,MATCH($A37,'סקרים לפי ערוץ'!$A:$A,0)) | C37: ישר! | D37: =INDEX('סקרים לפי ערוץ'!P:P,MATCH($A37,'סקרים לפי ערוץ'!$A:$A,0)) | E37: =COUNTIFS('מועמדים 2026'!$A:$A,$C37,'מועמדים 2026'!$D:$D,"נ",'מועמדים 2026'!$B:$B,"<="&$D37) | F37: =COUNTIFS('מועמדים 2026'!$A:$A,$C37,'מועמדים 2026'!$D:$D,"ז",'מועמדים 2026'!$B:$B,"<="&$D37) | G37: =IF($D37=0,0,$E37/$D37) | H37: =COUNTIFS('מועמדים 2026'!$A:$A,$C37) | I37: =IF(AND($D37>0,$H37=0),"אין נתוני מועמדים לחישוב","")
A38: ערוץ 14 | B38: =INDEX('סקרים לפי ערוץ'!$B:$B,MATCH($A38,'סקרים לפי ערוץ'!$A:$A,0)) | C38: הליכוד | D38: =INDEX('סקרים לפי ערוץ'!E:E,MATCH($A38,'סקרים לפי ערוץ'!$A:$A,0)) | E38: =COUNTIFS('מועמדים 2026'!$A:$A,$C38,'מועמדים 2026'!$D:$D,"נ",'מועמדים 2026'!$B:$B,"<="&$D38) | F38: =COUNTIFS('מועמדים 2026'!$A:$A,$C38,'מועמדים 2026'!$D:$D,"ז",'מועמדים 2026'!$B:$B,"<="&$D38) | G38: =IF($D38=0,0,$E38/$D38) | H38: =COUNTIFS('מועמדים 2026'!$A:$A,$C38) | I38: =IF(AND($D38>0,$H38=0),"אין נתוני מועמדים לחישוב","")
A39: ערוץ 14 | B39: =INDEX('סקרים לפי ערוץ'!$B:$B,MATCH($A39,'סקרים לפי ערוץ'!$A:$A,0)) | C39: יהדות התורה | D39: =INDEX('סקרים לפי ערוץ'!F:F,MATCH($A39,'סקרים לפי ערוץ'!$A:$A,0)) | E39: =COUNTIFS('מועמדים 2026'!$A:$A,$C39,'מועמדים 2026'!$D:$D,"נ",'מועמדים 2026'!$B:$B,"<="&$D39) | F39: =COUNTIFS('מועמדים 2026'!$A:$A,$C39,'מועמדים 2026'!$D:$D,"ז",'מועמדים 2026'!$B:$B,"<="&$D39) | G39: =IF($D39=0,0,$E39/$D39) | H39: =COUNTIFS('מועמדים 2026'!$A:$A,$C39) | I39: =IF(AND($D39>0,$H39=0),"אין נתוני מועמדים לחישוב","")
A40: ערוץ 14 | B40: =INDEX('סקרים לפי ערוץ'!$B:$B,MATCH($A40,'סקרים לפי ערוץ'!$A:$A,0)) | C40: ש"ס | D40: =INDEX('סקרים לפי ערוץ'!G:G,MATCH($A40,'סקרים לפי ערוץ'!$A:$A,0)) | E40: =COUNTIFS('מועמדים 2026'!$A:$A,$C40,'מועמדים 2026'!$D:$D,"נ",'מועמדים 2026'!$B:$B,"<="&$D40) | F40: =COUNTIFS('מועמדים 2026'!$A:$A,$C40,'מועמדים 2026'!$D:$D,"ז",'מועמדים 2026'!$B:$B,"<="&$D40) | G40: =IF($D40=0,0,$E40/$D40) | H40: =COUNTIFS('מועמדים 2026'!$A:$A,$C40) | I40: =IF(AND($D40>0,$H40=0),"אין נתוני מועמדים לחישוב","")
...
