Workbook

Sheet כל הרשימות
A1: מפלגה | B1: מיקום | C1: שם | D1: גבר/אישה
A2: מפלגת העבודה בראשות מרב מיכאלי | B2: 1 | C2: מיכאלי מירב
A3: מפלגת העבודה בראשות מרב מיכאלי | B3: 2 | C3: לזימי נעמה
A4: מפלגת העבודה בראשות מרב מיכאלי | B4: 3 | C4: קריב גלעד
A5: מפלגת העבודה בראשות מרב מיכאלי | B5: 4 | C5: רייטן מרום אפרת
A6: מפלגת העבודה בראשות מרב מיכאלי | B6: 5 | C6: שפע רם
A7: מפלגת העבודה בראשות מרב מיכאלי | B7: 6 | C7: מואטי אמילי חיה
A8: מפלגת העבודה בראשות מרב מיכאלי | B8: 7 | C8: פינק יאיר
A9: מפלגת העבודה בראשות מרב מיכאלי | B9: 8 | C9: מראענה אבתיסאם
A10: מפלגת העבודה בראשות מרב מיכאלי | B10: 9 | C10: בר לב עמר ישראל
A11: מפלגת העבודה בראשות מרב מיכאלי | B11: 10 | C11: ברון רון מהרטיה
A12: מפלגת העבודה בראשות מרב מיכאלי | B12: 11 | C12: ח'ניפס אמיר
A13: מפלגת העבודה בראשות מרב מיכאלי | B13: 12 | C13: נורי שקד מאיה
... A1413: דעת טוב ורע וברית שבט אברהם-עלה ירוק ואוסרת אל איסלמיה | B1413: 16 | C1413: קדישא אדיר

Sheet מסונן
A1: מפלגה | B1: מיקום | C1: שם | D1: מגדר
A2: מפלגת העבודה בראשות מרב מיכאלי | B2: 1 | C2: מיכאלי מירב | D2: נ
A3: מפלגת העבודה בראשות מרב מיכאלי | B3: 2 | C3: לזימי נעמה | D3: נ
A4: מפלגת העבודה בראשות מרב מיכאלי | B4: 3 | C4: קריב גלעד | D4: ז
A5: מפלגת העבודה בראשות מרב מיכאלי | B5: 4 | C5: רייטן מרום אפרת | D5: נ
A6: מפלגת העבודה בראשות מרב מיכאלי | B6: 5 | C6: שפע רם | D6: ז
A7: מפלגת העבודה בראשות מרב מיכאלי | B7: 6 | C7: מואטי אמילי חיה | D7: נ
A8: מפלגת העבודה בראשות מרב מיכאלי | B8: 7 | C8: פינק יאיר | D8: ז
A9: מפלגת העבודה בראשות מרב מיכאלי | B9: 8 | C9: מראענה אבתיסאם | D9: נ
A10: מפלגת העבודה בראשות מרב מיכאלי | B10: 9 | C10: בר לב עמר ישראל | D10: ז
A11: מפלגת העבודה בראשות מרב מיכאלי | B11: 10 | C11: ברוך רון מהרטיה | D11: נ
A12: מפלגת העבודה בראשות מרב מיכאלי | B12: 11 | C12: ח'ניפס אמיר | D12: ז
A13: מפלגת העבודה בראשות מרב מיכאלי | B13: 12 | C13: נורי שקד מאיה | D13: ז
... A1151: התאחדות הספרדים שומרי תורה תנועתו של מרן הרב עובדיה יוסף זצ"ל | B1151: 120 | C1151: בעדני חיים אהרון | D1151: ז

Sheet Sheet1
A1: מפלגה
A2: מפלגת העבודה בראשות מרב מיכאלי
A3: הבית היהודי בראשות איילת שקד
A4: יהדות התורה והשבת אגודת ישראל – דגל התורה
A5: בל"ד - אלתג'מוע אלווטני אלדמוקרטי בראשות סמי אבו שחאדה
A6: חד"ש תע"ל בראשות איימן עודה ואחמד טיבי
A7: הציונות הדתית בראשות בצלאל סמוטריץ ועוצמה יהודית בראשות איתמר בן גביר
A8: המחנה הממלכתי בהנהגת בני גנץ לראשות הממשלה
A9: ישראל ביתנו בראשות אביגדור ליברמן
A10: הליכוד בהנהגת בנימין נתניהו לראשות הממשלה
A11: מרצ השמאל של ישראל בראשות זהבה גלאון
A12: הרשימה הערבית המאוחדת
... A14: התאחדות הספרדים שומרי תורה תנועתו של מרן הרב עובדיה יוסף זצ"ל

Sheet חישוב
A1: מפלגה | B1: מנדטים בסקר | C1: כמות נשים צפויה | D1: כמות גברים צפויה
A2: הליכוד | B2: 26 | C2: =COUNTIFS(מסונן!A:A,Sheet1!A10,מסונן!D:D,"נ",מסונן!B:B,"<=" & חישוב!B2) -> 4 | D2: =B2-C2 -> 22
A3: ישראל ביתינו | B3: 10 | C3: =COUNTIFS(מסונן!A:A,Sheet1!A9,מסונן!D:D,"נ",מסונן!B:B,"<=" & חישוב!B3) -> 3 | D3: =B3-C3 -> 7
A4: המחנה הממלכתי | B4: 7 | C4: =COUNTIFS(מסונן!A:A,Sheet1!A8,מסונן!D:D,"נ",מסונן!B:B,"<=" & חישוב!B4) -> 2 | D4: =B4-C4 -> 5
A5: הדמוקרטים | B5: 11 | C5: =COUNTIFS(מסונן!A:A,Sheet1!A2,מסונן!D:D,"נ",מסונן!B:B,"<=" & חישוב!B5/2)+COUNTIFS(מסונן!A:A,Sheet1!A11,מסונן!D:D,"נ",מסונן!B:B,"<=" & חישוב!B5/2) -> 5 | D5: =B5-C5 -> 6
A6: יש עתיד | B6: 9 | C6: =COUNTIFS(מסונן!A:A,Sheet1!A13,מסונן!D:D,"נ",מסונן!B:B,"<=" & חישוב!B6) -> 3 | D6: =B6-C6 -> 6
A7: ש"ס | B7: 10 | C7: =COUNTIFS(מסונן!A:A,Sheet1!A14,מסונן!D:D,"נ",מסונן!B:B,"<=" & חישוב!B7) -> 0 | D7: =B7-C7 -> 10
A8: יהדות התורה | B8: 7 | C8: =COUNTIFS(מסונן!A:A,Sheet1!A4,מסונן!D:D,"נ",מסונן!B:B,"<=" & חישוב!B8) -> 0 | D8: =B8-C8 -> 7
A9: עוצמה יהודית | B9: 6 | C9: =COUNTIFS(מסונן!A:A,Sheet1!A7,מסונן!D:D,"נ",מסונן!B:B,"<=" & חישוב!B9) -> 1 | D9: =B9-C9 -> 5
A10: רע"מ | B10: 6 | C10: =COUNTIFS(מסונן!A:A,Sheet1!A12,מסונן!D:D,"נ",מסונן!B:B,"<=" & חישוב!B10) -> 1 | D10: =B10-C10 -> 5
A11: חדש-תע"ל | B11: 4 | C11: =COUNTIFS(מסונן!A:A,Sheet1!A6,מסונן!D:D,"נ",מסונן!B:B,"<=" & חישוב!B11) -> 1 | D11: =B11-C11 -> 3
A12: הציונות הדתית | B12: 0 | C12: =COUNTIFS(מסונן!A:A,Sheet1!A7,מסונן!D:D,"נ",מסונן!B:B,"<=" & חישוב!B12) -> 0 | D12: =B12-C12 -> 0

Sheet סקר 2026
A1: מפלגה | B1: ממוצע המדד (סקר) | C1: מעוגל | D1: מנדטים צפויים (סופי)
A2: הליכוד | B2: 20.7 | C2: =ROUND(B2,0) -> 21 | D2: =IF(C2<=3,0,C2) -> 21
A3: ישר! | B3: 22.1 | C3: =ROUND(B3,0) -> 22 | D3: =IF(C3<=3,0,C3) -> 22
A4: ביחד (בנט-לפיד) | B4: 11.8 | C4: =ROUND(B4,0) -> 12 | D4: =IF(C4<=3,0,C4) -> 12
A5: הדמוקרטים | B5: 8.8 | C5: =ROUND(B5,0) -> 9 | D5: =IF(C5<=3,0,C5) -> 9
A6: ישראל ביתנו | B6: 8 | C6: =ROUND(B6,0) -> 8 | D6: =IF(C6<=3,0,C6) -> 8
A7: ש"ס | B7: 7.7 | C7: =ROUND(B7,0) -> 8 | D7: =IF(C7<=3,0,C7) -> 8
A8: עוצמה יהודית | B8: 8 | C8: =ROUND(B8,0) -> 8 | D8: =IF(C8<=3,0,C8) -> 8
A9: יהדות התורה | B9: 7.5 | C9: =ROUND(B9,0) -> 8 | D9: =IF(C9<=3,0,C9) -> 8
A10: הרשימה המשותפת | B10: 8.1 | C10: =ROUND(B10,0) -> 8 | D10: =IF(C10<=3,0,C10) -> 8
A11: הציונות הדתית | B11: 6.2 | C11: =ROUND(B11,0) -> 6 | D11: =IF(C11<=3,0,C11) -> 6
A12: רע"מ | B12: 5.1 | C12: =ROUND(B12,0) -> 5 | D12: =IF(C12<=3,0,C12) -> 5
A13: כחול לבן | B13: 0.9 | C13: =ROUND(B13,0) -> 1 | D13: =IF(C13<=3,0,C13) -> 0
... A19: נעם לישראל | B19: 0 | C19: =ROUND(B19,0) -> 0 | D19: =IF(C19<=3,0,C19) -> 0

Sheet מועמדים 2026
A1: מפלגה | B1: מיקום | C1: שם | D1: מגדר | E1: ודאות/מקור
A2: ביחד (בנט-לפיד) | B2: 1 | C2: נפתלי בנט | D2: ז | E2: רשימה רשמית שהוצגה בכנס משותף של בנט ולפיד (6.9.2026)
A3: ביחד (בנט-לפיד) | B3: 2 | C3: יאיר לפיד | D3: ז | E3: רשימה רשמית שהוצגה בכנס משותף של בנט ולפיד (6.9.2026)
A4: ביחד (בנט-לפיד) | B4: 3 | C4: קרן טרנר | D4: נ | E4: רשימה רשמית שהוצגה בכנס משותף של בנט ולפיד (6.9.2026)
A5: ביחד (בנט-לפיד) | B5: 4 | C5: מירב בן ארי | D5: נ | E5: רשימה רשמית שהוצגה בכנס משותף של בנט ולפיד (6.9.2026)
A6: ביחד (בנט-לפיד) | B6: 5 | C6: לירן אבישר בן חורין | D6: נ | E6: רשימה רשמית שהוצגה בכנס משותף של בנט ולפיד (6.9.2026)
A7: ביחד (בנט-לפיד) | B7: 6 | C7: נעם תיבון | D7: ז | E7: רשימה רשמית שהוצגה בכנס משותף של בנט ולפיד (6.9.2026)
A8: ביחד (בנט-לפיד) | B8: 7 | C8: מיכל הירש נגרי | D8: נ | E8: רשימה רשמית שהוצגה בכנס משותף של בנט ולפיד (6.9.2026)
A9: ביחד (בנט-לפיד) | B9: 8 | C9: איתן גינזבורג | D9: ז | E9: רשימה רשמית שהוצגה בכנס משותף של בנט ולפיד (6.9.2026)
A10: ביחד (בנט-לפיד) | B10: 9 | C10: מירב כהן | D10: נ | E10: רשימה רשמית שהוצגה בכנס משותף של בנט ולפיד (6.9.2026)
A11: ביחד (בנט-לפיד) | B11: 10 | C11: יונתן שלו | D11: ז | E11: רשימה רשמית שהוצגה בכנס משותף של בנט ולפיד (6.9.2026)
A12: ביחד (בנט-לפיד) | B12: 11 | C12: ברוריה נעים ארמן | D12: נ | E12: רשימה רשמית שהוצגה בכנס משותף של בנט ולפיד (6.9.2026)
A13: ביחד (בנט-לפיד) | B13: 12 | C13: רם בן ברק | D13: ז | E13: רשימה רשמית שהוצגה בכנס משותף של בנט ולפיד (6.9.2026)
... A107: הציבור החרדי | B107: 4 | C107: גלאנץ זיוה רנית | D107: נ | E107: רשימה רשמית
A108: הציבור החרדי | B108: 5 | C108: מרדכי רובינשטיין | D108: ז
A109: הציבור החרדי | B109: 6 | C109: יצחק אדלרשטיין | D109: ז
A110: הציבור החרדי | B110: 7 | C110: אהרון אונגאר | D110: ז
A111: הציונות הדתית | B111: 1 | C111: בצלאל יואל סמוטריץ' | D111: ז | E111: עודכן לפי הרשימה הרשמית שהוגשה ליו"ר ועדת הבחירות המרכזית לכנסת ה-26, gov.il/he/pages/candidates-lists-26 - נבדק 14.9.2026 | מחליף רשימה שהייתה בסדר שגוי (מקומות 4-5 הפוכים בגיליון הקודם) וכללה מועמדים שנמצאים בפועל במקומות 12 ו-14 הרשמיים.
A112: הציונות הדתית | B112: 2 | C112: משה זלמן פייגלין | D112: ז | E112: עודכן לפי הרשימה הרשמית שהוגשה ליו"ר ועדת הבחירות המרכזית לכנסת ה-26, gov.il/he/pages/candidates-lists-26 - נבדק 14.9.2026 | מחליף רשימה שהייתה בסדר שגוי (מקומות 4-5 הפוכים בגיליון הקודם) וכללה מועמדים שנמצאים בפועל במקומות 12 ו-14 הרשמיים.
A113: הציונות הדתית | B113: 3 | C113: אורית מלכה סטרוק | D113: נ | E113: עודכן לפי הרשימה הרשמית שהוגשה ליו"ר ועדת הבחירות המרכזית לכנסת ה-26, gov.il/he/pages/candidates-lists-26 - נבדק 14.9.2026 | מחליף רשימה שהייתה בסדר שגוי (מקומות 4-5 הפוכים בגיליון הקודם) וכללה מועמדים שנמצאים בפועל במקומות 12 ו-14 הרשמיים.
A114: הציונות הדתית | B114: 4 | C114: שמחה דן רוטמן | D114: ז | E114: עודכן לפי הרשימה הרשמית שהוגשה ליו"ר ועדת הבחירות המרכזית לכנסת ה-26, gov.il/he/pages/candidates-lists-26 - נבדק 14.9.2026 | מחליף רשימה שהייתה בסדר שגוי (מקומות 4-5 הפוכים בגיליון הקודם) וכללה מועמדים שנמצאים בפועל במקומות 12 ו-14 הרשמיים.
A115: הציונות הדתית | B115: 5 | C115: צבי מור | D115: ז | E115: עודכן לפי הרשימה הרשמית שהוגשה ליו"ר ועדת הבחירות המרכזית לכנסת ה-26, gov.il/he/pages/candidates-lists-26 - נבדק 14.9.2026 | מחליף רשימה שהייתה בסדר שגוי (מקומות 4-5 הפוכים בגיליון הקודם) וכללה מועמדים שנמצאים בפועל במקומות 12 ו-14 הרשמיים.
A116: הציונות הדתית | B116: 6 | C116: איתמר מרדכי איתם | D116: ז | E116: עודכן לפי הרשימה הרשמית שהוגשה ליו"ר ועדת הבחירות המרכזית לכנסת ה-26, gov.il/he/pages/candidates-lists-26 - נבדק 14.9.2026 | מחליף רשימה שהייתה בסדר שגוי (מקומות 4-5 הפוכים בגיליון הקודם) וכללה מועמדים שנמצאים בפועל במקומות 12 ו-14 הרשמיים.
A117: הציונות הדתית | B117: 7 | C117: צבי ידידיה סוכות | D117: ז | E117: עודכן לפי הרשימה הרשמית שהוגשה ליו"ר ועדת הבחירות המרכזית לכנסת ה-26, gov.il/he/pages/candidates-lists-26 - נבדק 14.9.2026 | מחליף רשימה שהייתה בסדר שגוי (מקומות 4-5 הפוכים בגיליון הקודם) וכללה מועמדים שנמצאים בפועל במקומות 12 ו-14 הרשמיים.
A118: הציונות הדתית | B118: 8 | C118: יצחק חי זאגא | D118: ז | E118: עודכן לפי הרשימה הרשמית שהוגשה ליו"ר ועדת הבחירות המרכזית לכנסת ה-26, gov.il/he/pages/candidates-lists-26 - נבדק 14.9.2026 | מחליף רשימה שהייתה בסדר שגוי (מקומות 4-5 הפוכים בגיליון הקודם) וכללה מועמדים שנמצאים בפועל במקומות 12 ו-14 הרשמיים.
A119: הציונות הדתית | B119: 9 | C119: רעות בן חיים | D119: נ
A120: הציונות הדתית | B120: 10 | C120: עומר פציניאש וולדמן | D120: נ
A121: הציונות הדתית | B121: 11 | C121: ארקדי מוטר | D121: ז
A122: הציונות הדתית | B122: 12 | C122: אוהד טל | D122: ז
A123: הציונות הדתית | B123: 13 | C123: רועי קירשברג | D123: ז
A124: הציונות הדתית | B124: 14 | C124: עומר רחמים | D124: ז
A125: הציונות הדתית | B125: 15 | C125: סימון חסון | D125: ז
A126: הציונות הדתית | B126: 16 | C126: שמואל ששון | D126: ז
A127: הציונות הדתית | B127: 17 | C127: שיראל נהיר | D127: נ
A128: הציונות הדתית | B128: 18 | C128: צבי וישינגרד | D128: ז
A129: הרשימה המשותפת | B129: 1 | C129: יוסף גבארין | D129: ז | E129: עודכן לפי הרשימה הרשמית שהוגשה ליו"ר ועדת הבחירות המרכזית לכנסת ה-26, gov.il/he/pages/candidates-lists-26 - נבדק 14.9.2026 | מחליף רשימה שכללה מיקום 4 שגוי לחלוטין ('ג'עפר פרח' - לא קיים ברשימה הרשמית) ומיקומים 9-10 שהתאימו בפועל למקומות 10 ו-13 הרשמיים.
A130: הרשימה המשותפת | B130: 2 | C130: אחמד טיבי | D130: ז | E130: עודכן לפי הרשימה הרשמית שהוגשה ליו"ר ועדת הבחירות המרכזית לכנסת ה-26, gov.il/he/pages/candidates-lists-26 - נבדק 14.9.2026 | מחליף רשימה שכללה מיקום 4 שגוי לחלוטין ('ג'עפר פרח' - לא קיים ברשימה הרשמית) ומיקומים 9-10 שהתאימו בפועל למקומות 10 ו-13 הרשמיים.
A131: הרשימה המשותפת | B131: 3 | C131: עואודה בכר | D131: ז | E131: עודכן לפי הרשימה הרשמית שהוגשה ליו"ר ועדת הבחירות המרכזית לכנסת ה-26, gov.il/he/pages/candidates-lists-26 - נבדק 14.9.2026 | מחליף רשימה שכללה מיקום 4 שגוי לחלוטין ('ג'עפר פרח' - לא קיים ברשימה הרשמית) ומיקומים 9-10 שהתאימו בפועל למקומות 10 ו-13 הרשמיים.
A132: הרשימה המשותפת | B132: 4 | C132: עופר כסיף | D132: ז | E132: עודכן לפי הרשימה הרשמית שהוגשה ליו"ר ועדת הבחירות המרכזית לכנסת ה-26, gov.il/he/pages/candidates-lists-26 - נבדק 14.9.2026 | מחליף רשימה שכללה מיקום 4 שגוי לחלוטין ('ג'עפר פרח' - לא קיים ברשימה הרשמית) ומיקומים 9-10 שהתאימו בפועל למקומות 10 ו-13 הרשמיים.
A133: הרשימה המשותפת | B133: 5 | C133: יוסף עטאונה | D133: ז | E133: עודכן לפי הרשימה הרשמית שהוגשה ליו"ר ועדת הבחירות המרכזית לכנסת ה-26, gov.il/he/pages/candidates-lists-26 - נבדק 14.9.2026 | מחליף רשימה שכללה מיקום 4 שגוי לחלוטין ('ג'עפר פרח' - לא קיים ברשימה הרשמית) ומיקומים 9-10 שהתאימו בפועל למקומות 10 ו-13 הרשמיים.
...

Sheet חישוב 2026
A1: מפלגה | B1: מנדטים צפויים | C1: כמות נשים צפויה | D1: כמות גברים צפויה | E1: אחוז נשים צפוי | F1: הערות | G1: מנדטים נוכחיים (כנסת 25) | H1: נשים נוכחיות | I1: אחוז נשים נוכחי
A2: הליכוד | B2: =INDEX('סקר 2026'!$D:$D,MATCH(A2,'סקר 2026'!$A:$A,0)) -> 21 | C2: =COUNTIFS('מועמדים 2026'!$A:$A,A2,'מועמדים 2026'!$D:$D,"נ",'מועמדים 2026'!$B:$B,"<="&B2) -> 3 | D2: =COUNTIFS('מועמדים 2026'!$A:$A,A2,'מועמדים 2026'!$D:$D,"ז",'מועמדים 2026'!$B:$B,"<="&B2) -> 18 | E2: =IF(B2=0,0,C2/B2) -> 0.14285714 | F2: פריימריז אמיתי (לא מדגם) נערך בליכוד ב-17.8.2026 ופורסמו תוצאות סופיות (ynet, 17-18.8.2026). זה משנה משמעותית את ההנחה הקיימת בגיליון (שמבוססת על 'מדגם מתפקדים' פנימי מ-2-4.8.2026). המיקומים שלהלן הם 'מיקום כללי טרם שריונים' לפי הכתבה (לא בהכרח המיקום הסופי ברשימה, כי 8 שריונים של נתניהו במקומות 5,9,11,15,18,23,26,29 - לפי ויקיפדיה - משולבים בתוך הרשימה הסופית ומזיזים את כל מי שאחריהם). יש אף סתירה בין מקורות לגבי מיקומה המדויק של מירי רגב (8 לפי הכתבה הישירה, מול ניסוח מעורפל אחר שרמז ל-4). מומלץ להצליב עם הרשימה הרשמית שפרסם הליכוד (likud.org.il) או עם הגרפיקה המלאה בכתבה לפני עדכון בפועל. | G2: 32 | H2: 7 | I2: =IF(G2=0,0,H2/G2) -> 0.21875
A3: ישר! | B3: =INDEX('סקר 2026'!$D:$D,MATCH(A3,'סקר 2026'!$A:$A,0)) -> 22 | C3: =COUNTIFS('מועמדים 2026'!$A:$A,A3,'מועמדים 2026'!$D:$D,"נ",'מועמדים 2026'!$B:$B,"<="&B3) -> 11 | D3: =COUNTIFS('מועמדים 2026'!$A:$A,A3,'מועמדים 2026'!$D:$D,"ז",'מועמדים 2026'!$B:$B,"<="&B3) -> 11 | E3: =IF(B3=0,0,C3/B3) -> 0.5 | F3: מפלגת ישר! עם איזנקוט הגישה היום (7.9.2026) לוועדת הבחירות המרכזית רשימה רשמית וממוספרת של 40 מועמדים לכנסת ה-26 (וביקשה את האותיות 'דרך'), המחליפה לחלוטין את הרשימה המשוערת שהייתה בגיליון (שכללה שיבוצים שונים ו'מועמד/ת משוער/ת' במקומות 17-31 לפי הנחת 50/50). שם חדש שלא הוכר קודם בגיליון: עדי אלטשולר (מקום 4, יזמת חברתית). מגדר לא ודאי משם בלבד עבור: שי פישר (24), ליאן פולק דוד (25), זיו רוזן (27), גיל אבריאל (31), שירן בן דוד עוזרי (32), אלירן אליה (33) - יש לאמת ידנית. מקור: כיפה, 7.9.2026, https://www.kipa.co.il/חדשות/1231184-0/ | G3: 0 | H3: 0 | I3: =IF(G3=0,0,H3/G3) -> 0
A4: ביחד (בנט-לפיד) | B4: =INDEX('סקר 2026'!$D:$D,MATCH(A4,'סקר 2026'!$A:$A,0)) -> 12 | C4: =COUNTIFS('מועמדים 2026'!$A:$A,A4,'מועמדים 2026'!$D:$D,"נ",'מועמדים 2026'!$B:$B,"<="&B4) -> 6 | D4: =COUNTIFS('מועמדים 2026'!$A:$A,A4,'מועמדים 2026'!$D:$D,"ז",'מועמדים 2026'!$B:$B,"<="&B4) -> 6 | E4: =IF(B4=0,0,C4/B4) -> 0.5 | F4: בנט ולפיד חשפו רשימה מלאה וממוספרת של מפלגת "ביחד" ב-6.9.2026 (כנס חשיפה, דווח על ידי כיפה, ynet, mako, ישראל היום, סרוגים, בחדרי חרדים). הרשימה שונה מהותית מהאומדן הקודם בגיליון (שהתבסס על ניחוש יחס בנט-לפיד ודיווחים חלקיים). מקום 1-2 בנט/לפיד ידועים מזמן; מקום 3 ואילך כולו חדש ורשמי. שימו לב: זו רשימה שהוצגה בכנס מפלגתי, לא עדיין הגשה רשמית לוועדת הבחירות המרכזית. | G4: 24 | H4: 9 | I4: =IF(G4=0,0,H4/G4) -> 0.375
A5: הדמוקרטים | B5: =INDEX('סקר 2026'!$D:$D,MATCH(A5,'סקר 2026'!$A:$A,0)) -> 9 | C5: =COUNTIFS('מועמדים 2026'!$A:$A,A5,'מועמדים 2026'!$D:$D,"נ",'מועמדים 2026'!$B:$B,"<="&B5) -> 4 | D5: =COUNTIFS('מועמדים 2026'!$A:$A,A5,'מועמדים 2026'!$D:$D,"ז",'מועמדים 2026'!$B:$B,"<="&B5) -> 5 | E5: =IF(B5=0,0,C5/B5) -> 0.44444444 | F5: רשימה סופית רשמית (democrats.org.il/team, נשלף 5.8.2026); כל 20 המקומות הידועים נכללו, אך החישוב סופר רק את 10 המקומות הראשונים לפי המנדטים הצפויים בסקר | G5: 4 | H5: 3 | I5: =IF(G5=0,0,H5/G5) -> 0.75
A6: ישראל ביתנו | B6: =INDEX('סקר 2026'!$D:$D,MATCH(A6,'סקר 2026'!$A:$A,0)) -> 8 | C6: =COUNTIFS('מועמדים 2026'!$A:$A,A6,'מועמדים 2026'!$D:$D,"נ",'מועמדים 2026'!$B:$B,"<="&B6) -> 2 | D6: =COUNTIFS('מועמדים 2026'!$A:$A,A6,'מועמדים 2026'!$D:$D,"ז",'מועמדים 2026'!$B:$B,"<="&B6) -> 6 | E6: =IF(B6=0,0,C6/B6) -> 0.25 | F6: ליברמן הציג רשימה מלאה וממוספרת (25 מקומות) בכנס בחירות באקספו ת"א, 6.9.2026, ימיים לפני מועד סגירת הרשימות. מקורות: כיפה (ציטוט הרשימה המלאה במספור), וואלה, הארץ. מחליפה לחלוטין את האומדן הקודם בגיליון שהתבסס על ח"כים מכהנים ודיווחים חלקיים בלתי ממוספרים. | G6: 6 | H6: 2 | I6: =IF(G6=0,0,H6/G6) -> 0.33333333
A7: ש"ס | B7: =INDEX('סקר 2026'!$D:$D,MATCH(A7,'סקר 2026'!$A:$A,0)) -> 8 | C7: =COUNTIFS('מועמדים 2026'!$A:$A,A7,'מועמדים 2026'!$D:$D,"נ",'מועמדים 2026'!$B:$B,"<="&B7) -> 0 | D7: =COUNTIFS('מועמדים 2026'!$A:$A,A7,'מועמדים 2026'!$D:$D,"ז",'מועמדים 2026'!$B:$B,"<="&B7) -> 8 | E7: =IF(B7=0,0,C7/B7) -> 0 | F7: מפלגה חד-מגדרית באופן היסטורי | G7: 11 | H7: 0 | I7: =IF(G7=0,0,H7/G7) -> 0
A8: עוצמה יהודית | B8: =INDEX('סקר 2026'!$D:$D,MATCH(A8,'סקר 2026'!$A:$A,0)) -> 8 | C8: =COUNTIFS('מועמדים 2026'!$A:$A,A8,'מועמדים 2026'!$D:$D,"נ",'מועמדים 2026'!$B:$B,"<="&B8) -> 2 | D8: =COUNTIFS('מועמדים 2026'!$A:$A,A8,'מועמדים 2026'!$D:$D,"ז",'מועמדים 2026'!$B:$B,"<="&B8) -> 6 | E8: =IF(B8=0,0,C8/B8) -> 0.25 | F8: רה-ארגון ברשימת עוצמה יהודית: ח"כ צביקה פוגל (היה במקום 5 בגיליון) הודיע ב-4.9.2026 שלא יתמודד לכנסת הבאה. באותו יום הוכרז כי ח"כ טלי גוטליב (הליכוד, מקום 20) עוברת לעוצמה יהודית ותשובץ במקום 2; וסרלאוף זז למקום 3. בן גביר גם שיבץ את סון הר-מלך במקום 5 ואת קרויזר במקום 6. מיקומי אלמוג כהן ועמיחי אליהו (3-4 בגיליון) לא אושרו מחדש במפורש במקורות שנבדקו - ייתכן שהוזזו למקומות נמוכים יותר. יש לאמת מול פרסום רשמי נוסף לפני עדכון סופי. | G8: 6 | H8: 1 | I8: =IF(G8=0,0,H8/G8) -> 0.16666667
A9: יהדות התורה | B9: =INDEX('סקר 2026'!$D:$D,MATCH(A9,'סקר 2026'!$A:$A,0)) -> 8 | C9: =COUNTIFS('מועמדים 2026'!$A:$A,A9,'מועמדים 2026'!$D:$D,"נ",'מועמדים 2026'!$B:$B,"<="&B9) -> 0 | D9: =COUNTIFS('מועמדים 2026'!$A:$A,A9,'מועמדים 2026'!$D:$D,"ז",'מועמדים 2026'!$B:$B,"<="&B9) -> 8 | E9: =IF(B9=0,0,C9/B9) -> 0 | F9: מפלגה חד-מגדרית באופן היסטורי; מיקום 8 משוער | G9: 7 | H9: 0 | I9: =IF(G9=0,0,H9/G9) -> 0
A10: הרשימה המשותפת | B10: =INDEX('סקר 2026'!$D:$D,MATCH(A10,'סקר 2026'!$A:$A,0)) -> 8 | C10: =COUNTIFS('מועמדים 2026'!$A:$A,A10,'מועמדים 2026'!$D:$D,"נ",'מועמדים 2026'!$B:$B,"<="&B10) -> 1 | D10: =COUNTIFS('מועמדים 2026'!$A:$A,A10,'מועמדים 2026'!$D:$D,"ז",'מועמדים 2026'!$B:$B,"<="&B10) -> 7 | E10: =IF(B10=0,0,C10/B10) -> 0.125 | F10: רשימת חד"ש הרשמית מאתר המפלגה (hadash.org.il/list); אחמד טיבי (תע"ל) הוכנס במיקום 2 לפי בקשת המשתמש; איאס נאטור (מיקום 7) מחוץ לטווח 6 המנדטים | G10: 5 | H10: 1 | I10: =IF(G10=0,0,H10/G10) -> 0.2
A11: הציונות הדתית | B11: =INDEX('סקר 2026'!$D:$D,MATCH(A11,'סקר 2026'!$A:$A,0)) -> 6 | C11: =COUNTIFS('מועמדים 2026'!$A:$A,A11,'מועמדים 2026'!$D:$D,"נ",'מועמדים 2026'!$B:$B,"<="&B11) -> 1 | D11: =COUNTIFS('מועמדים 2026'!$A:$A,A11,'מועמדים 2026'!$D:$D,"ז",'מועמדים 2026'!$B:$B,"<="&B11) -> 5 | E11: =IF(B11=0,0,C11/B11) -> 0.16666667 | F11: איחוד טכני בין הציונות הדתית (סמוטריץ') לבין מפלגת 'זהות' (פייגלין) אושר במרכז הציונות הדתית (פורסם 1-2.9.2026); פייגלין ישובץ במקום 2 במקום ה'משוריין' שבגיליון. אם עופר וינטר ('עמך ישראל') היה מצטרף היה פייגלין יורד למקום 3 - אך וינטר סירב לאיחוד והגיש רשימה עצמאית (אושר 7.9.2026), כך שהשיבוץ הנוכחי יציב. | G11: 7 | H11: 2 | I11: =IF(G11=0,0,H11/G11) -> 0.28571429
A12: רע"מ | B12: =INDEX('סקר 2026'!$D:$D,MATCH(A12,'סקר 2026'!$A:$A,0)) -> 5 | C12: =COUNTIFS('מועמדים 2026'!$A:$A,A12,'מועמדים 2026'!$D:$D,"נ",'מועמדים 2026'!$B:$B,"<="&B12) -> 1 | D12: =COUNTIFS('מועמדים 2026'!$A:$A,A12,'מועמדים 2026'!$D:$D,"ז",'מועמדים 2026'!$B:$B,"<="&B12) -> 4 | E12: =IF(B12=0,0,C12/B12) -> 0.2 | F12: מושב 6 (יאסר חוג'יראת) לא ודאי; יואב סגלוביץ' נוסף במיקום 2 לפי בקשת המשתמש (הצטרפות מיש עתיד/ביחד) | G12: 5 | H12: 1 | I12: =IF(G12=0,0,H12/G12) -> 0.2
A13: עמך ישראל | B13: =INDEX('סקר 2026'!$D:$D,MATCH(A13,'סקר 2026'!$A:$A,0)) -> 0 | C13: =COUNTIFS('מועמדים 2026'!$A:$A,A13,'מועמדים 2026'!$D:$D,"נ",'מועמדים 2026'!$B:$B,"<="&B13) -> 0 | D13: =COUNTIFS('מועמדים 2026'!$A:$A,A13,'מועמדים 2026'!$D:$D,"ז",'מועמדים 2026'!$B:$B,"<="&B13) -> 0 | E13: =IF(B13=0,0,C13/B13) -> 0 | F13: מפלגה חדשה, הוקמה ע"י תא"ל (במיל') עופר וינטר; הושקה רשמית ב-25.8.2026. רשימה מבוססת דיווחי תקשורת ממסיבת ההשקה (ynet, ערוץ 7) - רשימה סופית וממוספרת רשמית טרם פורסמה לוועדת הבחירות המרכזית. | G13: 0 | H13: 0 | I13: =IF(G13=0,0,H13/G13) -> 0
... A15: הציבור החרדי | B15: =INDEX('סקר 2026'!$D:$D,MATCH(A15,'סקר 2026'!$A:$A,0)) -> 0 | C15: =COUNTIFS('מועמדים 2026'!$A:$A,A15,'מועמדים 2026'!$D:$D,"נ",'מועמדים 2026'!$B:$B,"<="&B15) -> 0 | D15: =COUNTIFS('מועמדים 2026'!$A:$A,A15,'מועמדים 2026'!$D:$D,"ז",'מועמדים 2026'!$B:$B,"<="&B15) -> 0 | E15: =IF(B15=0,0,C15/B15) -> 0 | F15: מלפגה חדשה | G15: 0 | H15: 0 | I15: =IF(G15=0,0,H15/G15) -> 0
A16: סה"כ | B16: =SUM(B2:B14) -> 119 | C16: =SUM(C2:C14) -> 32 | D16: =SUM(D2:D14) -> 87 | E16: =IF(B16=0,0,C16/B16) -> 0.26890756 | G16: =SUM(G2:G14) -> 107 | H16: =SUM(H2:H14) -> 26 | I16: =IF(G16=0,0,H16/G16) -> 0.24299065

Sheet סקרים לפי ערוץ
A1: כלי תקשורת | B1: תאריך הסקר | C1: סוקר | D1: מספר משיבים | E1: הליכוד | F1: יהדות התורה | G1: ש"ס | H1: הרשימה המשותפת | I1: ישראל ביתנו | J1: הדמוקרטים | K1: הציונות הדתית | L1: רע"מ | M1: עוצמה יהודית | N1: ביחד (בנט-לפיד) | O1: ישר! | P1: עמך ישראל | Q1: המילואימניקים-הכלכלית | R1: הציבור החרדי
A2: ערוץ 14 | B2: 2026-10-18 | C2: שלמה פילבר | D2: 559 | E2: 29 | F2: 8 | G2: 10 | H2: 7 | I2: 6 | J2: 8 | K2: 7 | L2: 6 | M2: 7 | N2: 10 | O2: 22 | P2: 0 | Q2: 0 | R2: 0
A3: כאן חדשות | B3: 2026-10-18 | C3: דודי חסיד | D3: 554 | E3: 21 | F3: 7 | G3: 8 | H3: 8 | I3: 8 | J3: 9 | K3: 7 | L3: 5 | M3: 8 | N3: 12 | O3: 23 | P3: 0 | Q3: 4 | R3: 0
A4: מעריב | B4: 2026-10-16 | C4: מנחם לזר | D4: 700 | E4: 18 | F4: 8 | G4: 7 | H4: 8 | I4: 8 | J4: 9 | K4: 6 | L4: 6 | M4: 8 | N4: 13 | O4: 21 | P4: 4 | Q4: 4 | R4: 0
A5: ישראל היום | B5: 2026-10-15 | C5: דודי חסיד | D5: 551 | E5: 21 | F5: 7 | G5: 7 | H5: 9 | I5: 8 | J5: 8 | K5: 6 | L5: 5 | M5: 9 | N5: 12 | O5: 24 | P5: 0 | Q5: 4 | R5: 0
A6: זמן ישראל | B6: 2026-10-15 | C6: יוסי טאטיקה | D6: 500 | E6: 20 | F6: 8 | G6: 8 | H6: 8 | I6: 9 | J6: 8 | K6: 6 | L6: 5 | M6: 7 | N6: 11 | O6: 26 | P6: 0 | Q6: 4 | R6: 0
A7: חדשות 13 | B7: 2026-10-14 | C7: המדד | D7: 1018 | E7: 18 | F7: 8 | G7: 7 | H7: 9 | I7: 9 | J7: 9 | K7: 6 | L7: 6 | M7: 8 | N7: 12 | O7: 20 | P7: 4 | Q7: 4 | R7: 0
A8: ערוץ 16 | B8: 2026-10-13 | C8: יצחק כ״ץ | D8: 500 | E8: 18 | F8: 8 | G8: 7 | H8: 8 | I8: 7 | J8: 9 | K8: 6 | L8: 5 | M8: 9 | N8: 13 | O8: 21 | P8: 4 | Q8: 5 | R8: 0
A9: חדשות 12 | B9: 2026-10-12 | C9: מנו גבע | D9: 509 | E9: 20 | F9: 7 | G9: 8 | H9: 8 | I9: 9 | J9: 9 | K9: 6 | L9: 5 | M9: 8 | N9: 13 | O9: 23 | P9: 0 | Q9: 4 | R9: 0
A10: וואלה | B10: 2026-10-12 | C10: מנחם לזר | D10: 500 | E10: 20 | F10: 8 | G10: 7 | H10: 8 | I10: 9 | J10: 10 | K10: 6 | L10: 5 | M10: 8 | N10: 13 | O10: 22 | P10: 0 | Q10: 4 | R10: 0
A11: i24 news | B11: 2026-10-08 | C11: צוריאל שרון | D11: 518 | E11: 26 | F11: 8 | G11: 7 | H11: 7 | I11: 7 | J11: 10 | K11: 6 | L11: 5 | M11: 9 | N11: 11 | O11: 20 | P11: 4 | Q11: 0 | R11: 0

Sheet חישוב לפי ערוץ
A1: כלי תקשורת | B1: תאריך הסקר | C1: מפלגה | D1: מנדטים | E1: כמות נשים צפויה | F1: כמות גברים צפויה | G1: אחוז נשים צפוי | H1: מועמדים ידועים (סה"כ) | I1: הערה
A2: ערוץ 14 | B2: =INDEX('סקרים לפי ערוץ'!$B:$B,MATCH($A2,'סקרים לפי ערוץ'!$A:$A,0)) -> 2026-10-18 | C2: הליכוד | D2: =INDEX('סקרים לפי ערוץ'!E:E,MATCH($A2,'סקרים לפי ערוץ'!$A:$A,0)) -> 29 | E2: =COUNTIFS('מועמדים 2026'!$A:$A,$C2,'מועמדים 2026'!$D:$D,"נ",'מועמדים 2026'!$B:$B,"<="&$D2) -> 4 | F2: =COUNTIFS('מועמדים 2026'!$A:$A,$C2,'מועמדים 2026'!$D:$D,"ז",'מועמדים 2026'!$B:$B,"<="&$D2) -> 25 | G2: =IF($D2=0,0,$E2/$D2) -> 0.13793103 | H2: =COUNTIFS('מועמדים 2026'!$A:$A,$C2) -> 36 | I2: =IF(AND($D2>0,$H2=0),"אין נתוני מועמדים לחישוב",IF(D2>H2,"חסרים מועמדים ברשימה",""))
A3: ערוץ 14 | B3: =INDEX('סקרים לפי ערוץ'!$B:$B,MATCH($A3,'סקרים לפי ערוץ'!$A:$A,0)) -> 2026-10-18 | C3: יהדות התורה | D3: =INDEX('סקרים לפי ערוץ'!F:F,MATCH($A3,'סקרים לפי ערוץ'!$A:$A,0)) -> 8 | E3: =COUNTIFS('מועמדים 2026'!$A:$A,$C3,'מועמדים 2026'!$D:$D,"נ",'מועמדים 2026'!$B:$B,"<="&$D3) -> 0 | F3: =COUNTIFS('מועמדים 2026'!$A:$A,$C3,'מועמדים 2026'!$D:$D,"ז",'מועמדים 2026'!$B:$B,"<="&$D3) -> 8 | G3: =IF($D3=0,0,$E3/$D3) -> 0 | H3: =COUNTIFS('מועמדים 2026'!$A:$A,$C3) -> 9 | I3: =IF(AND($D3>0,$H3=0),"אין נתוני מועמדים לחישוב",IF(D3>H3,"חסרים מועמדים ברשימה",""))
A4: ערוץ 14 | B4: =INDEX('סקרים לפי ערוץ'!$B:$B,MATCH($A4,'סקרים לפי ערוץ'!$A:$A,0)) -> 2026-10-18 | C4: ש"ס | D4: =INDEX('סקרים לפי ערוץ'!G:G,MATCH($A4,'סקרים לפי ערוץ'!$A:$A,0)) -> 10 | E4: =COUNTIFS('מועמדים 2026'!$A:$A,$C4,'מועמדים 2026'!$D:$D,"נ",'מועמדים 2026'!$B:$B,"<="&$D4) -> 0 | F4: =COUNTIFS('מועמדים 2026'!$A:$A,$C4,'מועמדים 2026'!$D:$D,"ז",'מועמדים 2026'!$B:$B,"<="&$D4) -> 10 | G4: =IF($D4=0,0,$E4/$D4) -> 0 | H4: =COUNTIFS('מועמדים 2026'!$A:$A,$C4) -> 11 | I4: =IF(AND($D4>0,$H4=0),"אין נתוני מועמדים לחישוב",IF(D4>H4,"חסרים מועמדים ברשימה",""))
A5: ערוץ 14 | B5: =INDEX('סקרים לפי ערוץ'!$B:$B,MATCH($A5,'סקרים לפי ערוץ'!$A:$A,0)) -> 2026-10-18 | C5: כחול לבן | D5: =INDEX('סקרים לפי ערוץ'!#REF!,MATCH($A5,'סקרים לפי ערוץ'!$A:$A,0)) -> #REF! | E5: =COUNTIFS('מועמדים 2026'!$A:$A,$C5,'מועמדים 2026'!$D:$D,"נ",'מועמדים 2026'!$B:$B,"<="&$D5) -> 0 | F5: =COUNTIFS('מועמדים 2026'!$A:$A,$C5,'מועמדים 2026'!$D:$D,"ז",'מועמדים 2026'!$B:$B,"<="&$D5) -> 0 | G5: =IF($D5=0,0,$E5/$D5) -> #REF! | H5: =COUNTIFS('מועמדים 2026'!$A:$A,$C5) -> 5 | I5: =IF(AND($D5>0,$H5=0),"אין נתוני מועמדים לחישוב",IF(D5>H5,"חסרים מועמדים ברשימה","")) -> #REF!
A6: ערוץ 14 | B6: =INDEX('סקרים לפי ערוץ'!$B:$B,MATCH($A6,'סקרים לפי ערוץ'!$A:$A,0)) -> 2026-10-18 | C6: הרשימה המשותפת | D6: =INDEX('סקרים לפי ערוץ'!H:H,MATCH($A6,'סקרים לפי ערוץ'!$A:$A,0)) -> 7 | E6: =COUNTIFS('מועמדים 2026'!$A:$A,$C6,'מועמדים 2026'!$D:$D,"נ",'מועמדים 2026'!$B:$B,"<="&$D6) -> 1 | F6: =COUNTIFS('מועמדים 2026'!$A:$A,$C6,'מועמדים 2026'!$D:$D,"ז",'מועמדים 2026'!$B:$B,"<="&$D6) -> 6 | G6: =IF($D6=0,0,$E6/$D6) -> 0.14285714 | H6: =COUNTIFS('מועמדים 2026'!$A:$A,$C6) -> 10 | I6: =IF(AND($D6>0,$H6=0),"אין נתוני מועמדים לחישוב",IF(D6>H6,"חסרים מועמדים ברשימה",""))
A7: ערוץ 14 | B7: =INDEX('סקרים לפי ערוץ'!$B:$B,MATCH($A7,'סקרים לפי ערוץ'!$A:$A,0)) -> 2026-10-18 | C7: ישראל ביתנו | D7: =INDEX('סקרים לפי ערוץ'!I:I,MATCH($A7,'סקרים לפי ערוץ'!$A:$A,0)) -> 6 | E7: =COUNTIFS('מועמדים 2026'!$A:$A,$C7,'מועמדים 2026'!$D:$D,"נ",'מועמדים 2026'!$B:$B,"<="&$D7) -> 2 | F7: =COUNTIFS('מועמדים 2026'!$A:$A,$C7,'מועמדים 2026'!$D:$D,"ז",'מועמדים 2026'!$B:$B,"<="&$D7) -> 4 | G7: =IF($D7=0,0,$E7/$D7) -> 0.33333333 | H7: =COUNTIFS('מועמדים 2026'!$A:$A,$C7) -> 20 | I7: =IF(AND($D7>0,$H7=0),"אין נתוני מועמדים לחישוב",IF(D7>H7,"חסרים מועמדים ברשימה",""))
A8: ערוץ 14 | B8: =INDEX('סקרים לפי ערוץ'!$B:$B,MATCH($A8,'סקרים לפי ערוץ'!$A:$A,0)) -> 2026-10-18 | C8: הדמוקרטים | D8: =INDEX('סקרים לפי ערוץ'!J:J,MATCH($A8,'סקרים לפי ערוץ'!$A:$A,0)) -> 8 | E8: =COUNTIFS('מועמדים 2026'!$A:$A,$C8,'מועמדים 2026'!$D:$D,"נ",'מועמדים 2026'!$B:$B,"<="&$D8) -> 4 | F8: =COUNTIFS('מועמדים 2026'!$A:$A,$C8,'מועמדים 2026'!$D:$D,"ז",'מועמדים 2026'!$B:$B,"<="&$D8) -> 4 | G8: =IF($D8=0,0,$E8/$D8) -> 0.5 | H8: =COUNTIFS('מועמדים 2026'!$A:$A,$C8) -> 20 | I8: =IF(AND($D8>0,$H8=0),"אין נתוני מועמדים לחישוב",IF(D8>H8,"חסרים מועמדים ברשימה",""))
A9: ערוץ 14 | B9: =INDEX('סקרים לפי ערוץ'!$B:$B,MATCH($A9,'סקרים לפי ערוץ'!$A:$A,0)) -> 2026-10-18 | C9: הציונות הדתית | D9: =INDEX('סקרים לפי ערוץ'!K:K,MATCH($A9,'סקרים לפי ערוץ'!$A:$A,0)) -> 7 | E9: =COUNTIFS('מועמדים 2026'!$A:$A,$C9,'מועמדים 2026'!$D:$D,"נ",'מועמדים 2026'!$B:$B,"<="&$D9) -> 1 | F9: =COUNTIFS('מועמדים 2026'!$A:$A,$C9,'מועמדים 2026'!$D:$D,"ז",'מועמדים 2026'!$B:$B,"<="&$D9) -> 6 | G9: =IF($D9=0,0,$E9/$D9) -> 0.14285714 | H9: =COUNTIFS('מועמדים 2026'!$A:$A,$C9) -> 18 | I9: =IF(AND($D9>0,$H9=0),"אין נתוני מועמדים לחישוב",IF(D9>H9,"חסרים מועמדים ברשימה",""))
A10: ערוץ 14 | B10: =INDEX('סקרים לפי ערוץ'!$B:$B,MATCH($A10,'סקרים לפי ערוץ'!$A:$A,0)) -> 2026-10-18 | C10: רע"מ | D10: =INDEX('סקרים לפי ערוץ'!L:L,MATCH($A10,'סקרים לפי ערוץ'!$A:$A,0)) -> 6 | E10: =COUNTIFS('מועמדים 2026'!$A:$A,$C10,'מועמדים 2026'!$D:$D,"נ",'מועמדים 2026'!$B:$B,"<="&$D10) -> 1 | F10: =COUNTIFS('מועמדים 2026'!$A:$A,$C10,'מועמדים 2026'!$D:$D,"ז",'מועמדים 2026'!$B:$B,"<="&$D10) -> 5 | G10: =IF($D10=0,0,$E10/$D10) -> 0.16666667 | H10: =COUNTIFS('מועמדים 2026'!$A:$A,$C10) -> 6 | I10: =IF(AND($D10>0,$H10=0),"אין נתוני מועמדים לחישוב",IF(D10>H10,"חסרים מועמדים ברשימה",""))
A11: ערוץ 14 | B11: =INDEX('סקרים לפי ערוץ'!$B:$B,MATCH($A11,'סקרים לפי ערוץ'!$A:$A,0)) -> 2026-10-18 | C11: עוצמה יהודית | D11: =INDEX('סקרים לפי ערוץ'!M:M,MATCH($A11,'סקרים לפי ערוץ'!$A:$A,0)) -> 7 | E11: =COUNTIFS('מועמדים 2026'!$A:$A,$C11,'מועמדים 2026'!$D:$D,"נ",'מועמדים 2026'!$B:$B,"<="&$D11) -> 2 | F11: =COUNTIFS('מועמדים 2026'!$A:$A,$C11,'מועמדים 2026'!$D:$D,"ז",'מועמדים 2026'!$B:$B,"<="&$D11) -> 5 | G11: =IF($D11=0,0,$E11/$D11) -> 0.28571429 | H11: =COUNTIFS('מועמדים 2026'!$A:$A,$C11) -> 17 | I11: =IF(AND($D11>0,$H11=0),"אין נתוני מועמדים לחישוב",IF(D11>H11,"חסרים מועמדים ברשימה",""))
A12: ערוץ 14 | B12: =INDEX('סקרים לפי ערוץ'!$B:$B,MATCH($A12,'סקרים לפי ערוץ'!$A:$A,0)) -> 2026-10-18 | C12: ביחד (בנט-לפיד) | D12: =INDEX('סקרים לפי ערוץ'!N:N,MATCH($A12,'סקרים לפי ערוץ'!$A:$A,0)) -> 10 | E12: =COUNTIFS('מועמדים 2026'!$A:$A,$C12,'מועמדים 2026'!$D:$D,"נ",'מועמדים 2026'!$B:$B,"<="&$D12) -> 5 | F12: =COUNTIFS('מועמדים 2026'!$A:$A,$C12,'מועמדים 2026'!$D:$D,"ז",'מועמדים 2026'!$B:$B,"<="&$D12) -> 5 | G12: =IF($D12=0,0,$E12/$D12) -> 0.5 | H12: =COUNTIFS('מועמדים 2026'!$A:$A,$C12) -> 26 | I12: =IF(AND($D12>0,$H12=0),"אין נתוני מועמדים לחישוב",IF(D12>H12,"חסרים מועמדים ברשימה",""))
A13: ערוץ 14 | B13: =INDEX('סקרים לפי ערוץ'!$B:$B,MATCH($A13,'סקרים לפי ערוץ'!$A:$A,0)) -> 2026-10-18 | C13: ישר! | D13: =INDEX('סקרים לפי ערוץ'!O:O,MATCH($A13,'סקרים לפי ערוץ'!$A:$A,0)) -> 22 | E13: =COUNTIFS('מועמדים 2026'!$A:$A,$C13,'מועמדים 2026'!$D:$D,"נ",'מועמדים 2026'!$B:$B,"<="&$D13) -> 11 | F13: =COUNTIFS('מועמדים 2026'!$A:$A,$C13,'מועמדים 2026'!$D:$D,"ז",'מועמדים 2026'!$B:$B,"<="&$D13) -> 11 | G13: =IF($D13=0,0,$E13/$D13) -> 0.5 | H13: =COUNTIFS('מועמדים 2026'!$A:$A,$C13) -> 40 | I13: =IF(AND($D13>0,$H13=0),"אין נתוני מועמדים לחישוב",IF(D13>H13,"חסרים מועמדים ברשימה",""))
A14: ערוץ 14 | B14: =INDEX('סקרים לפי ערוץ'!$B:$B,MATCH($A14,'סקרים לפי ערוץ'!$A:$A,0)) -> 2026-10-18 | C14: עמך ישראל | D14: =INDEX('סקרים לפי ערוץ'!P:P,MATCH($A14,'סקרים לפי ערוץ'!$A:$A,0)) -> 0 | E14: =COUNTIFS('מועמדים 2026'!$A:$A,$C14,'מועמדים 2026'!$D:$D,"נ",'מועמדים 2026'!$B:$B,"<="&$D14) -> 0 | F14: =COUNTIFS('מועמדים 2026'!$A:$A,$C14,'מועמדים 2026'!$D:$D,"ז",'מועמדים 2026'!$B:$B,"<="&$D14) -> 0 | G14: =IF($D14=0,0,$E14/$D14) -> 0 | H14: =COUNTIFS('מועמדים 2026'!$A:$A,$C14) -> 11 | I14: =IF(AND($D14>0,$H14=0),"אין נתוני מועמדים לחישוב",IF(D14>H14,"חסרים מועמדים ברשימה",""))
A15: ערוץ 14 | B15: =INDEX('סקרים לפי ערוץ'!$B:$B,MATCH($A15,'סקרים לפי ערוץ'!$A:$A,0)) -> 2026-10-18 | C15: המילואימניקים-הכלכלית | D15: =INDEX('סקרים לפי ערוץ'!Q:Q,MATCH($A15,'סקרים לפי ערוץ'!$A:$A,0)) -> 0 | E15: =COUNTIFS('מועמדים 2026'!$A:$A,$C15,'מועמדים 2026'!$D:$D,"נ",'מועמדים 2026'!$B:$B,"<="&$D15) -> 0 | F15: =COUNTIFS('מועמדים 2026'!$A:$A,$C15,'מועמדים 2026'!$D:$D,"ז",'מועמדים 2026'!$B:$B,"<="&$D15) -> 0 | G15: =IF($D15=0,0,$E15/$D15) -> 0 | H15: =COUNTIFS('מועמדים 2026'!$A:$A,$C15) -> 20 | I15: =IF(AND($D15>0,$H15=0),"אין נתוני מועמדים לחישוב",IF(D15>H15,"חסרים מועמדים ברשימה",""))
A16: כאן חדשות | B16: =INDEX('סקרים לפי ערוץ'!$B:$B,MATCH($A16,'סקרים לפי ערוץ'!$A:$A,0)) -> 2026-10-18 | C16: הליכוד | D16: =INDEX('סקרים לפי ערוץ'!E:E,MATCH($A16,'סקרים לפי ערוץ'!$A:$A,0)) -> 21 | E16: =COUNTIFS('מועמדים 2026'!$A:$A,$C16,'מועמדים 2026'!$D:$D,"נ",'מועמדים 2026'!$B:$B,"<="&$D16) -> 3 | F16: =COUNTIFS('מועמדים 2026'!$A:$A,$C16,'מועמדים 2026'!$D:$D,"ז",'מועמדים 2026'!$B:$B,"<="&$D16) -> 18 | G16: =IF($D16=0,0,$E16/$D16) -> 0.14285714 | H16: =COUNTIFS('מועמדים 2026'!$A:$A,$C16) -> 36 | I16: =IF(AND($D16>0,$H16=0),"אין נתוני מועמדים לחישוב",IF(D16>H16,"חסרים מועמדים ברשימה",""))
A17: כאן חדשות | B17: =INDEX('סקרים לפי ערוץ'!$B:$B,MATCH($A17,'סקרים לפי ערוץ'!$A:$A,0)) -> 2026-10-18 | C17: יהדות התורה | D17: =INDEX('סקרים לפי ערוץ'!F:F,MATCH($A17,'סקרים לפי ערוץ'!$A:$A,0)) -> 7 | E17: =COUNTIFS('מועמדים 2026'!$A:$A,$C17,'מועמדים 2026'!$D:$D,"נ",'מועמדים 2026'!$B:$B,"<="&$D17) -> 0 | F17: =COUNTIFS('מועמדים 2026'!$A:$A,$C17,'מועמדים 2026'!$D:$D,"ז",'מועמדים 2026'!$B:$B,"<="&$D17) -> 7 | G17: =IF($D17=0,0,$E17/$D17) -> 0 | H17: =COUNTIFS('מועמדים 2026'!$A:$A,$C17) -> 9 | I17: =IF(AND($D17>0,$H17=0),"אין נתוני מועמדים לחישוב",IF(D17>H17,"חסרים מועמדים ברשימה",""))
A18: כאן חדשות | B18: =INDEX('סקרים לפי ערוץ'!$B:$B,MATCH($A18,'סקרים לפי ערוץ'!$A:$A,0)) -> 2026-10-18 | C18: ש"ס | D18: =INDEX('סקרים לפי ערוץ'!G:G,MATCH($A18,'סקרים לפי ערוץ'!$A:$A,0)) -> 8 | E18: =COUNTIFS('מועמדים 2026'!$A:$A,$C18,'מועמדים 2026'!$D:$D,"נ",'מועמדים 2026'!$B:$B,"<="&$D18) -> 0 | F18: =COUNTIFS('מועמדים 2026'!$A:$A,$C18,'מועמדים 2026'!$D:$D,"ז",'מועמדים 2026'!$B:$B,"<="&$D18) -> 8 | G18: =IF($D18=0,0,$E18/$D18) -> 0 | H18: =COUNTIFS('מועמדים 2026'!$A:$A,$C18) -> 11 | I18: =IF(AND($D18>0,$H18=0),"אין נתוני מועמדים לחישוב",IF(D18>H18,"חסרים מועמדים ברשימה",""))
A19: כאן חדשות | B19: =INDEX('סקרים לפי ערוץ'!$B:$B,MATCH($A19,'סקרים לפי ערוץ'!$A:$A,0)) -> 2026-10-18 | C19: כחול לבן | D19: =INDEX('סקרים לפי ערוץ'!#REF!,MATCH($A19,'סקרים לפי ערוץ'!$A:$A,0)) -> #REF! | E19: =COUNTIFS('מועמדים 2026'!$A:$A,$C19,'מועמדים 2026'!$D:$D,"נ",'מועמדים 2026'!$B:$B,"<="&$D19) -> 0 | F19: =COUNTIFS('מועמדים 2026'!$A:$A,$C19,'מועמדים 2026'!$D:$D,"ז",'מועמדים 2026'!$B:$B,"<="&$D19) -> 0 | G19: =IF($D19=0,0,$E19/$D19) -> #REF! | H19: =COUNTIFS('מועמדים 2026'!$A:$A,$C19) -> 5 | I19: =IF(AND($D19>0,$H19=0),"אין נתוני מועמדים לחישוב",IF(D19>H19,"חסרים מועמדים ברשימה","")) -> #REF!
A20: כאן חדשות | B20: =INDEX('סקרים לפי ערוץ'!$B:$B,MATCH($A20,'סקרים לפי ערוץ'!$A:$A,0)) -> 2026-10-18 | C20: הרשימה המשותפת | D20: =INDEX('סקרים לפי ערוץ'!H:H,MATCH($A20,'סקרים לפי ערוץ'!$A:$A,0)) -> 8 | E20: =COUNTIFS('מועמדים 2026'!$A:$A,$C20,'מועמדים 2026'!$D:$D,"נ",'מועמדים 2026'!$B:$B,"<="&$D20) -> 1 | F20: =COUNTIFS('מועמדים 2026'!$A:$A,$C20,'מועמדים 2026'!$D:$D,"ז",'מועמדים 2026'!$B:$B,"<="&$D20) -> 7 | G20: =IF($D20=0,0,$E20/$D20) -> 0.125 | H20: =COUNTIFS('מועמדים 2026'!$A:$A,$C20) -> 10 | I20: =IF(AND($D20>0,$H20=0),"אין נתוני מועמדים לחישוב",IF(D20>H20,"חסרים מועמדים ברשימה",""))
A21: כאן חדשות | B21: =INDEX('סקרים לפי ערוץ'!$B:$B,MATCH($A21,'סקרים לפי ערוץ'!$A:$A,0)) -> 2026-10-18 | C21: ישראל ביתנו | D21: =INDEX('סקרים לפי ערוץ'!I:I,MATCH($A21,'סקרים לפי ערוץ'!$A:$A,0)) -> 8 | E21: =COUNTIFS('מועמדים 2026'!$A:$A,$C21,'מועמדים 2026'!$D:$D,"נ",'מועמדים 2026'!$B:$B,"<="&$D21) -> 2 | F21: =COUNTIFS('מועמדים 2026'!$A:$A,$C21,'מועמדים 2026'!$D:$D,"ז",'מועמדים 2026'!$B:$B,"<="&$D21) -> 6 | G21: =IF($D21=0,0,$E21/$D21) -> 0.25 | H21: =COUNTIFS('מועמדים 2026'!$A:$A,$C21) -> 20 | I21: =IF(AND($D21>0,$H21=0),"אין נתוני מועמדים לחישוב",IF(D21>H21,"חסרים מועמדים ברשימה",""))
A22: כאן חדשות | B22: =INDEX('סקרים לפי ערוץ'!$B:$B,MATCH($A22,'סקרים לפי ערוץ'!$A:$A,0)) -> 2026-10-18 | C22: הדמוקרטים | D22: =INDEX('סקרים לפי ערוץ'!J:J,MATCH($A22,'סקרים לפי ערוץ'!$A:$A,0)) -> 9 | E22: =COUNTIFS('מועמדים 2026'!$A:$A,$C22,'מועמדים 2026'!$D:$D,"נ",'מועמדים 2026'!$B:$B,"<="&$D22) -> 4 | F22: =COUNTIFS('מועמדים 2026'!$A:$A,$C22,'מועמדים 2026'!$D:$D,"ז",'מועמדים 2026'!$B:$B,"<="&$D22) -> 5 | G22: =IF($D22=0,0,$E22/$D22) -> 0.44444444 | H22: =COUNTIFS('מועמדים 2026'!$A:$A,$C22) -> 20 | I22: =IF(AND($D22>0,$H22=0),"אין נתוני מועמדים לחישוב",IF(D22>H22,"חסרים מועמדים ברשימה",""))
A23: כאן חדשות | B23: =INDEX('סקרים לפי ערוץ'!$B:$B,MATCH($A23,'סקרים לפי ערוץ'!$A:$A,0)) -> 2026-10-18 | C23: הציונות הדתית | D23: =INDEX('סקרים לפי ערוץ'!K:K,MATCH($A23,'סקרים לפי ערוץ'!$A:$A,0)) -> 7 | E23: =COUNTIFS('מועמדים 2026'!$A:$A,$C23,'מועמדים 2026'!$D:$D,"נ",'מועמדים 2026'!$B:$B,"<="&$D23) -> 1 | F23: =COUNTIFS('מועמדים 2026'!$A:$A,$C23,'מועמדים 2026'!$D:$D,"ז",'מועמדים 2026'!$B:$B,"<="&$D23) -> 6 | G23: =IF($D23=0,0,$E23/$D23) -> 0.14285714 | H23: =COUNTIFS('מועמדים 2026'!$A:$A,$C23) -> 18 | I23: =IF(AND($D23>0,$H23=0),"אין נתוני מועמדים לחישוב",IF(D23>H23,"חסרים מועמדים ברשימה",""))
A24: כאן חדשות | B24: =INDEX('סקרים לפי ערוץ'!$B:$B,MATCH($A24,'סקרים לפי ערוץ'!$A:$A,0)) -> 2026-10-18 | C24: רע"מ | D24: =INDEX('סקרים לפי ערוץ'!L:L,MATCH($A24,'סקרים לפי ערוץ'!$A:$A,0)) -> 5 | E24: =COUNTIFS('מועמדים 2026'!$A:$A,$C24,'מועמדים 2026'!$D:$D,"נ",'מועמדים 2026'!$B:$B,"<="&$D24) -> 1 | F24: =COUNTIFS('מועמדים 2026'!$A:$A,$C24,'מועמדים 2026'!$D:$D,"ז",'מועמדים 2026'!$B:$B,"<="&$D24) -> 4 | G24: =IF($D24=0,0,$E24/$D24) -> 0.2 | H24: =COUNTIFS('מועמדים 2026'!$A:$A,$C24) -> 6 | I24: =IF(AND($D24>0,$H24=0),"אין נתוני מועמדים לחישוב",IF(D24>H24,"חסרים מועמדים ברשימה",""))
A25: כאן חדשות | B25: =INDEX('סקרים לפי ערוץ'!$B:$B,MATCH($A25,'סקרים לפי ערוץ'!$A:$A,0)) -> 2026-10-18 | C25: עוצמה יהודית | D25: =INDEX('סקרים לפי ערוץ'!M:M,MATCH($A25,'סקרים לפי ערוץ'!$A:$A,0)) -> 8 | E25: =COUNTIFS('מועמדים 2026'!$A:$A,$C25,'מועמדים 2026'!$D:$D,"נ",'מועמדים 2026'!$B:$B,"<="&$D25) -> 2 | F25: =COUNTIFS('מועמדים 2026'!$A:$A,$C25,'מועמדים 2026'!$D:$D,"ז",'מועמדים 2026'!$B:$B,"<="&$D25) -> 6 | G25: =IF($D25=0,0,$E25/$D25) -> 0.25 | H25: =COUNTIFS('מועמדים 2026'!$A:$A,$C25) -> 17 | I25: =IF(AND($D25>0,$H25=0),"אין נתוני מועמדים לחישוב",IF(D25>H25,"חסרים מועמדים ברשימה",""))
A26: כאן חדשות | B26: =INDEX('סקרים לפי ערוץ'!$B:$B,MATCH($A26,'סקרים לפי ערוץ'!$A:$A,0)) -> 2026-10-18 | C26: ביחד (בנט-לפיד) | D26: =INDEX('סקרים לפי ערוץ'!N:N,MATCH($A26,'סקרים לפי ערוץ'!$A:$A,0)) -> 12 | E26: =COUNTIFS('מועמדים 2026'!$A:$A,$C26,'מועמדים 2026'!$D:$D,"נ",'מועמדים 2026'!$B:$B,"<="&$D26) -> 6 | F26: =COUNTIFS('מועמדים 2026'!$A:$A,$C26,'מועמדים 2026'!$D:$D,"ז",'מועמדים 2026'!$B:$B,"<="&$D26) -> 6 | G26: =IF($D26=0,0,$E26/$D26) -> 0.5 | H26: =COUNTIFS('מועמדים 2026'!$A:$A,$C26) -> 26 | I26: =IF(AND($D26>0,$H26=0),"אין נתוני מועמדים לחישוב",IF(D26>H26,"חסרים מועמדים ברשימה",""))
A27: כאן חדשות | B27: =INDEX('סקרים לפי ערוץ'!$B:$B,MATCH($A27,'סקרים לפי ערוץ'!$A:$A,0)) -> 2026-10-18 | C27: ישר! | D27: =INDEX('סקרים לפי ערוץ'!O:O,MATCH($A27,'סקרים לפי ערוץ'!$A:$A,0)) -> 23 | E27: =COUNTIFS('מועמדים 2026'!$A:$A,$C27,'מועמדים 2026'!$D:$D,"נ",'מועמדים 2026'!$B:$B,"<="&$D27) -> 11 | F27: =COUNTIFS('מועמדים 2026'!$A:$A,$C27,'מועמדים 2026'!$D:$D,"ז",'מועמדים 2026'!$B:$B,"<="&$D27) -> 12 | G27: =IF($D27=0,0,$E27/$D27) -> 0.47826087 | H27: =COUNTIFS('מועמדים 2026'!$A:$A,$C27) -> 40 | I27: =IF(AND($D27>0,$H27=0),"אין נתוני מועמדים לחישוב",IF(D27>H27,"חסרים מועמדים ברשימה",""))
A28: כאן חדשות | B28: =INDEX('סקרים לפי ערוץ'!$B:$B,MATCH($A28,'סקרים לפי ערוץ'!$A:$A,0)) -> 2026-10-18 | C28: עמך ישראל | D28: =INDEX('סקרים לפי ערוץ'!P:P,MATCH($A28,'סקרים לפי ערוץ'!$A:$A,0)) -> 0 | E28: =COUNTIFS('מועמדים 2026'!$A:$A,$C28,'מועמדים 2026'!$D:$D,"נ",'מועמדים 2026'!$B:$B,"<="&$D28) -> 0 | F28: =COUNTIFS('מועמדים 2026'!$A:$A,$C28,'מועמדים 2026'!$D:$D,"ז",'מועמדים 2026'!$B:$B,"<="&$D28) -> 0 | G28: =IF($D28=0,0,$E28/$D28) -> 0 | H28: =COUNTIFS('מועמדים 2026'!$A:$A,$C28) -> 11 | I28: =IF(AND($D28>0,$H28=0),"אין נתוני מועמדים לחישוב",IF(D28>H28,"חסרים מועמדים ברשימה",""))
A29: כאן חדשות | B29: =INDEX('סקרים לפי ערוץ'!$B:$B,MATCH($A29,'סקרים לפי ערוץ'!$A:$A,0)) -> 2026-10-18 | C29: המילואימניקים-הכלכלית | D29: =INDEX('סקרים לפי ערוץ'!Q:Q,MATCH($A29,'סקרים לפי ערוץ'!$A:$A,0)) -> 4 | E29: =COUNTIFS('מועמדים 2026'!$A:$A,$C29,'מועמדים 2026'!$D:$D,"נ",'מועמדים 2026'!$B:$B,"<="&$D29) -> 1 | F29: =COUNTIFS('מועמדים 2026'!$A:$A,$C29,'מועמדים 2026'!$D:$D,"ז",'מועמדים 2026'!$B:$B,"<="&$D29) -> 3 | G29: =IF($D29=0,0,$E29/$D29) -> 0.25 | H29: =COUNTIFS('מועמדים 2026'!$A:$A,$C29) -> 20 | I29: =IF(AND($D29>0,$H29=0),"אין נתוני מועמדים לחישוב",IF(D29>H29,"חסרים מועמדים ברשימה",""))
A30: מעריב | B30: =INDEX('סקרים לפי ערוץ'!$B:$B,MATCH($A30,'סקרים לפי ערוץ'!$A:$A,0)) -> 2026-10-16 | C30: הליכוד | D30: =INDEX('סקרים לפי ערוץ'!E:E,MATCH($A30,'סקרים לפי ערוץ'!$A:$A,0)) -> 18 | E30: =COUNTIFS('מועמדים 2026'!$A:$A,$C30,'מועמדים 2026'!$D:$D,"נ",'מועמדים 2026'!$B:$B,"<="&$D30) -> 2 | F30: =COUNTIFS('מועמדים 2026'!$A:$A,$C30,'מועמדים 2026'!$D:$D,"ז",'מועמדים 2026'!$B:$B,"<="&$D30) -> 16 | G30: =IF($D30=0,0,$E30/$D30) -> 0.11111111 | H30: =COUNTIFS('מועמדים 2026'!$A:$A,$C30) -> 36 | I30: =IF(AND($D30>0,$H30=0),"אין נתוני מועמדים לחישוב",IF(D30>H30,"חסרים מועמדים ברשימה",""))
A31: מעריב | B31: =INDEX('סקרים לפי ערוץ'!$B:$B,MATCH($A31,'סקרים לפי ערוץ'!$A:$A,0)) -> 2026-10-16 | C31: יהדות התורה | D31: =INDEX('סקרים לפי ערוץ'!F:F,MATCH($A31,'סקרים לפי ערוץ'!$A:$A,0)) -> 8 | E31: =COUNTIFS('מועמדים 2026'!$A:$A,$C31,'מועמדים 2026'!$D:$D,"נ",'מועמדים 2026'!$B:$B,"<="&$D31) -> 0 | F31: =COUNTIFS('מועמדים 2026'!$A:$A,$C31,'מועמדים 2026'!$D:$D,"ז",'מועמדים 2026'!$B:$B,"<="&$D31) -> 8 | G31: =IF($D31=0,0,$E31/$D31) -> 0 | H31: =COUNTIFS('מועמדים 2026'!$A:$A,$C31) -> 9 | I31: =IF(AND($D31>0,$H31=0),"אין נתוני מועמדים לחישוב",IF(D31>H31,"חסרים מועמדים ברשימה",""))
A32: מעריב | B32: =INDEX('סקרים לפי ערוץ'!$B:$B,MATCH($A32,'סקרים לפי ערוץ'!$A:$A,0)) -> 2026-10-16 | C32: ש"ס | D32: =INDEX('סקרים לפי ערוץ'!G:G,MATCH($A32,'סקרים לפי ערוץ'!$A:$A,0)) -> 7 | E32: =COUNTIFS('מועמדים 2026'!$A:$A,$C32,'מועמדים 2026'!$D:$D,"נ",'מועמדים 2026'!$B:$B,"<="&$D32) -> 0 | F32: =COUNTIFS('מועמדים 2026'!$A:$A,$C32,'מועמדים 2026'!$D:$D,"ז",'מועמדים 2026'!$B:$B,"<="&$D32) -> 7 | G32: =IF($D32=0,0,$E32/$D32) -> 0 | H32: =COUNTIFS('מועמדים 2026'!$A:$A,$C32) -> 11 | I32: =IF(AND($D32>0,$H32=0),"אין נתוני מועמדים לחישוב",IF(D32>H32,"חסרים מועמדים ברשימה",""))
A33: מעריב | B33: =INDEX('סקרים לפי ערוץ'!$B:$B,MATCH($A33,'סקרים לפי ערוץ'!$A:$A,0)) -> 2026-10-16 | C33: כחול לבן | D33: =INDEX('סקרים לפי ערוץ'!#REF!,MATCH($A33,'סקרים לפי ערוץ'!$A:$A,0)) -> #REF! | E33: =COUNTIFS('מועמדים 2026'!$A:$A,$C33,'מועמדים 2026'!$D:$D,"נ",'מועמדים 2026'!$B:$B,"<="&$D33) -> 0 | F33: =COUNTIFS('מועמדים 2026'!$A:$A,$C33,'מועמדים 2026'!$D:$D,"ז",'מועמדים 2026'!$B:$B,"<="&$D33) -> 0 | G33: =IF($D33=0,0,$E33/$D33) -> #REF! | H33: =COUNTIFS('מועמדים 2026'!$A:$A,$C33) -> 5 | I33: =IF(AND($D33>0,$H33=0),"אין נתוני מועמדים לחישוב",IF(D33>H33,"חסרים מועמדים ברשימה","")) -> #REF!
A34: מעריב | B34: =INDEX('סקרים לפי ערוץ'!$B:$B,MATCH($A34,'סקרים לפי ערוץ'!$A:$A,0)) -> 2026-10-16 | C34: הרשימה המשותפת | D34: =INDEX('סקרים לפי ערוץ'!H:H,MATCH($A34,'סקרים לפי ערוץ'!$A:$A,0)) -> 8 | E34: =COUNTIFS('מועמדים 2026'!$A:$A,$C34,'מועמדים 2026'!$D:$D,"נ",'מועמדים 2026'!$B:$B,"<="&$D34) -> 1 | F34: =COUNTIFS('מועמדים 2026'!$A:$A,$C34,'מועמדים 2026'!$D:$D,"ז",'מועמדים 2026'!$B:$B,"<="&$D34) -> 7 | G34: =IF($D34=0,0,$E34/$D34) -> 0.125 | H34: =COUNTIFS('מועמדים 2026'!$A:$A,$C34) -> 10 | I34: =IF(AND($D34>0,$H34=0),"אין נתוני מועמדים לחישוב",IF(D34>H34,"חסרים מועמדים ברשימה",""))
A35: מעריב | B35: =INDEX('סקרים לפי ערוץ'!$B:$B,MATCH($A35,'סקרים לפי ערוץ'!$A:$A,0)) -> 2026-10-16 | C35: ישראל ביתנו | D35: =INDEX('סקרים לפי ערוץ'!I:I,MATCH($A35,'סקרים לפי ערוץ'!$A:$A,0)) -> 8 | E35: =COUNTIFS('מועמדים 2026'!$A:$A,$C35,'מועמדים 2026'!$D:$D,"נ",'מועמדים 2026'!$B:$B,"<="&$D35) -> 2 | F35: =COUNTIFS('מועמדים 2026'!$A:$A,$C35,'מועמדים 2026'!$D:$D,"ז",'מועמדים 2026'!$B:$B,"<="&$D35) -> 6 | G35: =IF($D35=0,0,$E35/$D35) -> 0.25 | H35: =COUNTIFS('מועמדים 2026'!$A:$A,$C35) -> 20 | I35: =IF(AND($D35>0,$H35=0),"אין נתוני מועמדים לחישוב",IF(D35>H35,"חסרים מועמדים ברשימה",""))
A36: מעריב | B36: =INDEX('סקרים לפי ערוץ'!$B:$B,MATCH($A36,'סקרים לפי ערוץ'!$A:$A,0)) -> 2026-10-16 | C36: הדמוקרטים | D36: =INDEX('סקרים לפי ערוץ'!J:J,MATCH($A36,'סקרים לפי ערוץ'!$A:$A,0)) -> 9 | E36: =COUNTIFS('מועמדים 2026'!$A:$A,$C36,'מועמדים 2026'!$D:$D,"נ",'מועמדים 2026'!$B:$B,"<="&$D36) -> 4 | F36: =COUNTIFS('מועמדים 2026'!$A:$A,$C36,'מועמדים 2026'!$D:$D,"ז",'מועמדים 2026'!$B:$B,"<="&$D36) -> 5 | G36: =IF($D36=0,0,$E36/$D36) -> 0.44444444 | H36: =COUNTIFS('מועמדים 2026'!$A:$A,$C36) -> 20 | I36: =IF(AND($D36>0,$H36=0),"אין נתוני מועמדים לחישוב",IF(D36>H36,"חסרים מועמדים ברשימה",""))
A37: מעריב | B37: =INDEX('סקרים לפי ערוץ'!$B:$B,MATCH($A37,'סקרים לפי ערוץ'!$A:$A,0)) -> 2026-10-16 | C37: הציונות הדתית | D37: =INDEX('סקרים לפי ערוץ'!K:K,MATCH($A37,'סקרים לפי ערוץ'!$A:$A,0)) -> 6 | E37: =COUNTIFS('מועמדים 2026'!$A:$A,$C37,'מועמדים 2026'!$D:$D,"נ",'מועמדים 2026'!$B:$B,"<="&$D37) -> 1 | F37: =COUNTIFS('מועמדים 2026'!$A:$A,$C37,'מועמדים 2026'!$D:$D,"ז",'מועמדים 2026'!$B:$B,"<="&$D37) -> 5 | G37: =IF($D37=0,0,$E37/$D37) -> 0.16666667 | H37: =COUNTIFS('מועמדים 2026'!$A:$A,$C37) -> 18 | I37: =IF(AND($D37>0,$H37=0),"אין נתוני מועמדים לחישוב",IF(D37>H37,"חסרים מועמדים ברשימה",""))
A38: מעריב | B38: =INDEX('סקרים לפי ערוץ'!$B:$B,MATCH($A38,'סקרים לפי ערוץ'!$A:$A,0)) -> 2026-10-16 | C38: רע"מ | D38: =INDEX('סקרים לפי ערוץ'!L:L,MATCH($A38,'סקרים לפי ערוץ'!$A:$A,0)) -> 6 | E38: =COUNTIFS('מועמדים 2026'!$A:$A,$C38,'מועמדים 2026'!$D:$D,"נ",'מועמדים 2026'!$B:$B,"<="&$D38) -> 1 | F38: =COUNTIFS('מועמדים 2026'!$A:$A,$C38,'מועמדים 2026'!$D:$D,"ז",'מועמדים 2026'!$B:$B,"<="&$D38) -> 5 | G38: =IF($D38=0,0,$E38/$D38) -> 0.16666667 | H38: =COUNTIFS('מועמדים 2026'!$A:$A,$C38) -> 6 | I38: =IF(AND($D38>0,$H38=0),"אין נתוני מועמדים לחישוב",IF(D38>H38,"חסרים מועמדים ברשימה",""))
A39: מעריב | B39: =INDEX('סקרים לפי ערוץ'!$B:$B,MATCH($A39,'סקרים לפי ערוץ'!$A:$A,0)) -> 2026-10-16 | C39: עוצמה יהודית | D39: =INDEX('סקרים לפי ערוץ'!M:M,MATCH($A39,'סקרים לפי ערוץ'!$A:$A,0)) -> 8 | E39: =COUNTIFS('מועמדים 2026'!$A:$A,$C39,'מועמדים 2026'!$D:$D,"נ",'מועמדים 2026'!$B:$B,"<="&$D39) -> 2 | F39: =COUNTIFS('מועמדים 2026'!$A:$A,$C39,'מועמדים 2026'!$D:$D,"ז",'מועמדים 2026'!$B:$B,"<="&$D39) -> 6 | G39: =IF($D39=0,0,$E39/$D39) -> 0.25 | H39: =COUNTIFS('מועמדים 2026'!$A:$A,$C39) -> 17 | I39: =IF(AND($D39>0,$H39=0),"אין נתוני מועמדים לחישוב",IF(D39>H39,"חסרים מועמדים ברשימה",""))
A40: מעריב | B40: =INDEX('סקרים לפי ערוץ'!$B:$B,MATCH($A40,'סקרים לפי ערוץ'!$A:$A,0)) -> 2026-10-16 | C40: ביחד (בנט-לפיד) | D40: =INDEX('סקרים לפי ערוץ'!N:N,MATCH($A40,'סקרים לפי ערוץ'!$A:$A,0)) -> 13 | E40: =COUNTIFS('מועמדים 2026'!$A:$A,$C40,'מועמדים 2026'!$D:$D,"נ",'מועמדים 2026'!$B:$B,"<="&$D40) -> 6 | F40: =COUNTIFS('מועמדים 2026'!$A:$A,$C40,'מועמדים 2026'!$D:$D,"ז",'מועמדים 2026'!$B:$B,"<="&$D40) -> 7 | G40: =IF($D40=0,0,$E40/$D40) -> 0.46153846 | H40: =COUNTIFS('מועמדים 2026'!$A:$A,$C40) -> 26 | I40: =IF(AND($D40>0,$H40=0),"אין נתוני מועמדים לחישוב",IF(D40>H40,"חסרים מועמדים ברשימה",""))
...
